Workbook
Name 식재료DB: '🥬 식재료 DB'!$C$7:$H$121

Sheet 📊 대시보드
B2: EVEREST RESTAURANT GROUP · 메뉴 원가 관리 시스템 (식재료·고정비 자동 연동)
B5: 전체 메뉴 | D5: 식재료 원가율 | F5: 총 원가율 (식재료+고정) | H5: 원가율 현황
B6: =COUNTA(C12:C111)-COUNTBLANK(C12:C111) -> 78 | D6: =IFERROR(AVERAGEIF(F12:F111,">0",IF(E12:E111>0,F12:F111/E12:E111,0)),"–") -> – | F6: =IFERROR(AVERAGEIF(H12:H111,">0",I12:I111),"–") -> 0.56775968 | H6: =IFERROR("✅"&COUNTIF(K12:K111,"*양호*")&" 🟡"&COUNTIF(K12:K111,"*주의*")&" 🔴"&COUNTIF(K12:K111,"*과다*"),"–") -> ✅0 🟡0 🔴89
B10: 📋 전체 메뉴 원가 현황 ─ 식재료 DB·고정비용 DB 수정 시 자동 갱신
B11: No. | C11: 메뉴명 | D11: 카테고리 | E11: 판매가(원) | F11: 식재료원가 | G11: 고정비용 | H11: 총 원가 | I11: 총 원가율 | J11: 마진(원) | K11: 판정
B12: 🍗 닭고기 커리
B13: 1 | C13: 치킨머커니 | D13: 🍗 닭고기 커리 | E13: ='🍗 닭고기 커리'!E8 -> 13000 | F13: ='🍗 닭고기 커리'!F8 -> 1734.247 | G13: ='🍗 닭고기 커리'!G8 -> 8583.8619 | H13: ='🍗 닭고기 커리'!H8 -> 6849.6149 | I13: ='🍗 닭고기 커리'!I8 -> 0.52689345 | J13: =IFERROR('🍗 닭고기 커리'!E8-'🍗 닭고기 커리'!H8,"") -> 6150.3851 | K13: ='🍗 닭고기 커리'!J8 -> 🔴 과다
B14: 2 | C14: 치킨 커리 | D14: 🍗 닭고기 커리 | E14: ='🍗 닭고기 커리'!E29 -> 12000 | F14: ='🍗 닭고기 커리'!F29 -> 1558.0248 | G14: ='🍗 닭고기 커리'!G29 -> 7923.5648 | H14: ='🍗 닭고기 커리'!H29 -> 6365.54 | I14: ='🍗 닭고기 커리'!I29 -> 0.53046167 | J14: =IFERROR('🍗 닭고기 커리'!E29-'🍗 닭고기 커리'!H29,"") -> 5634.46 | K14: ='🍗 닭고기 커리'!J29 -> 🔴 과다
B15: 3 | C15: 치킨 마살라 | D15: 🍗 닭고기 커리 | E15: ='🍗 닭고기 커리'!E50 -> 12000 | F15: ='🍗 닭고기 커리'!F50 -> 1859.4382 | G15: ='🍗 닭고기 커리'!G50 -> 7923.5648 | H15: ='🍗 닭고기 커리'!H50 -> 6064.1266 | I15: ='🍗 닭고기 커리'!I50 -> 0.50534388 | J15: =IFERROR('🍗 닭고기 커리'!E50-'🍗 닭고기 커리'!H50,"") -> 5935.8734 | K15: ='🍗 닭고기 커리'!J50 -> 🔴 과다
B16: 4 | C16: 커다이 치킨 | D16: 🍗 닭고기 커리 | E16: ='🍗 닭고기 커리'!E71 -> 13000 | F16: ='🍗 닭고기 커리'!F71 -> 1125.1149 | G16: ='🍗 닭고기 커리'!G71 -> 8583.8619 | H16: ='🍗 닭고기 커리'!H71 -> 7458.747 | I16: ='🍗 닭고기 커리'!I71 -> 0.57374977 | J16: =IFERROR('🍗 닭고기 커리'!E71-'🍗 닭고기 커리'!H71,"") -> 5541.253 | K16: ='🍗 닭고기 커리'!J71 -> 🔴 과다
B17: 5 | C17: 치킨 티카 마살라 | D17: 🍗 닭고기 커리 | E17: ='🍗 닭고기 커리'!E92 -> 13000 | F17: ='🍗 닭고기 커리'!F92 -> 2570.2871 | G17: ='🍗 닭고기 커리'!G92 -> 8583.8619 | H17: ='🍗 닭고기 커리'!H92 -> 6013.5747 | I17: ='🍗 닭고기 커리'!I92 -> 0.46258267 | J17: =IFERROR('🍗 닭고기 커리'!E92-'🍗 닭고기 커리'!H92,"") -> 6986.4253 | K17: ='🍗 닭고기 커리'!J92 -> 🔴 과다
B18: 6 | C18: 스페셜 커리치킨 | D18: 🍗 닭고기 커리 | E18: ='🍗 닭고기 커리'!E113 -> 14000 | F18: ='🍗 닭고기 커리'!F113 -> 648.03405 | G18: ='🍗 닭고기 커리'!G113 -> 9244.1589 | H18: ='🍗 닭고기 커리'!H113 -> 8596.1249 | I18: ='🍗 닭고기 커리'!I113 -> 0.61400892 | J18: =IFERROR('🍗 닭고기 커리'!E113-'🍗 닭고기 커리'!H113,"") -> 5403.8751 | K18: ='🍗 닭고기 커리'!J113 -> 🔴 과다
B19: 7 | C19: 베이비 커리 | D19: 🍗 닭고기 커리 | E19: ='🍗 닭고기 커리'!E134 -> 13000 | F19: ='🍗 닭고기 커리'!F134 -> 655.13086 | G19: ='🍗 닭고기 커리'!G134 -> 8583.8619 | H19: ='🍗 닭고기 커리'!H134 -> 7928.731 | I19: ='🍗 닭고기 커리'!I134 -> 0.60990238 | J19: =IFERROR('🍗 닭고기 커리'!E134-'🍗 닭고기 커리'!H134,"") -> 5071.269 | K19: ='🍗 닭고기 커리'!J134 -> 🔴 과다
B20: 8 | C20: 진저 치킨 | D20: 🍗 닭고기 커리 | E20: ='🍗 닭고기 커리'!E155 -> 12000 | F20: ='🍗 닭고기 커리'!F155 -> 1880.5556 | G20: ='🍗 닭고기 커리'!G155 -> 7923.5648 | H20: ='🍗 닭고기 커리'!H155 -> 6043.0092 | I20: ='🍗 닭고기 커리'!I155 -> 0.5035841 | J20: =IFERROR('🍗 닭고기 커리'!E155-'🍗 닭고기 커리'!H155,"") -> 5956.9908 | K20: ='🍗 닭고기 커리'!J155 -> 🔴 과다
B21: 9 | C21: 치킨 빈달루 | D21: 🍗 닭고기 커리 | E21: ='🍗 닭고기 커리'!E176 -> 14000 | F21: ='🍗 닭고기 커리'!F176 -> 1767.4136 | G21: ='🍗 닭고기 커리'!G176 -> 9244.1589 | H21: ='🍗 닭고기 커리'!H176 -> 7476.7453 | I21: ='🍗 닭고기 커리'!I176 -> 0.53405323 | J21: =IFERROR('🍗 닭고기 커리'!E176-'🍗 닭고기 커리'!H176,"") -> 6523.2547 | K21: ='🍗 닭고기 커리'!J176 -> 🔴 과다
B22: 10 | C22: 치킨 코르마 | D22: 🍗 닭고기 커리 | E22: ='🍗 닭고기 커리'!E197 -> 12000 | F22: ='🍗 닭고기 커리'!F197 -> 1093.3859 | G22: ='🍗 닭고기 커리'!G197 -> 7923.5648 | H22: ='🍗 닭고기 커리'!H197 -> 6830.1789 | I22: ='🍗 닭고기 커리'!I197 -> 0.56918158 | J22: =IFERROR('🍗 닭고기 커리'!E197-'🍗 닭고기 커리'!H197,"") -> 5169.8211 | K22: ='🍗 닭고기 커리'!J197 -> 🔴 과다
B23: 73 | C23: 커다이치킨 | D23: 🍗 닭고기 커리 | E23: ='🍗 닭고기 커리'!E218 -> 12000 | F23: ='🍗 닭고기 커리'!F218 -> 1125.1149 | G23: ='🍗 닭고기 커리'!G218 -> 7923.5648 | H23: ='🍗 닭고기 커리'!H218 -> 6798.4499 | I23: ='🍗 닭고기 커리'!I218 -> 0.5665375 | J23: =IFERROR('🍗 닭고기 커리'!E218-'🍗 닭고기 커리'!H218,"") -> 5201.5501 | K23: ='🍗 닭고기 커리'!J218 -> 🔴 과다
B24: 74 | C24: 버터 치킨 | D24: 🍗 닭고기 커리 | E24: ='🍗 닭고기 커리'!E239 -> 15000 | F24: ='🍗 닭고기 커리'!F239 -> 1093.3859 | G24: ='🍗 닭고기 커리'!G239 -> 9904.456 | H24: ='🍗 닭고기 커리'!H239 -> 8811.0701 | I24: ='🍗 닭고기 커리'!I239 -> 0.58740468 | J24: =IFERROR('🍗 닭고기 커리'!E239-'🍗 닭고기 커리'!H239,"") -> 6188.9299 | K24: ='🍗 닭고기 커리'!J239 -> 🔴 과다
B25: 40 | C25: 치킨 칠리 | D25: 🍗 닭고기 커리 | E25: ='🍗 닭고기 커리'!E260 -> 11000 | F25: ='🍗 닭고기 커리'!F260 -> 1626.6906 | G25: ='🍗 닭고기 커리'!G260 -> 7263.2677 | H25: ='🍗 닭고기 커리'!H260 -> 5636.5772 | I25: ='🍗 닭고기 커리'!I260 -> 0.51241611 | J25: =IFERROR('🍗 닭고기 커리'!E260-'🍗 닭고기 커리'!H260,"") -> 5363.4228 | K25: ='🍗 닭고기 커리'!J260 -> 🔴 과다
B26: 86 | C26: 스페셜치킨커리 | D26: 🍗 닭고기 커리 | E26: ='🍗 닭고기 커리'!E285 -> 14000 | F26: ='🍗 닭고기 커리'!F285 -> 1405.5174 | G26: ='🍗 닭고기 커리'!G285 -> 9244.1589 | H26: ='🍗 닭고기 커리'!H285 -> 7838.6415 | I26: ='🍗 닭고기 커리'!I285 -> 0.55990296 | J26: =IFERROR('🍗 닭고기 커리'!E285-'🍗 닭고기 커리'!H285,"") -> 6161.3585 | K26: ='🍗 닭고기 커리'!J285 -> 🔴 과다
B27: 🐑 양고기 커리
B28: 12 | C28: 머턴 커리 | D28: 🐑 양고기 커리 | E28: ='🐑 양고기 커리'!E8 -> 13000 | F28: ='🐑 양고기 커리'!F8 -> 1868.0248 | G28: ='🐑 양고기 커리'!G8 -> 8583.8619 | H28: ='🐑 양고기 커리'!H8 -> 6715.8371 | I28: ='🐑 양고기 커리'!I8 -> 0.51660285 | J28: =IFERROR('🐑 양고기 커리'!E8-'🐑 양고기 커리'!H8,"") -> 6284.1629 | K28: ='🐑 양고기 커리'!J8 -> 🔴 과다
B29: 13 | C29: 머턴 마살라 | D29: 🐑 양고기 커리 | E29: ='🐑 양고기 커리'!E29 -> 14000 | F29: ='🐑 양고기 커리'!F29 -> 2135.3998 | G29: ='🐑 양고기 커리'!G29 -> 9244.1589 | H29: ='🐑 양고기 커리'!H29 -> 7108.7592 | I29: ='🐑 양고기 커리'!I29 -> 0.50776851 | J29: =IFERROR('🐑 양고기 커리'!E29-'🐑 양고기 커리'!H29,"") -> 6891.2408 | K29: ='🐑 양고기 커리'!J29 -> 🔴 과다
B30: 14 | C30: 머턴 도 피아자 | D30: 🐑 양고기 커리 | E30: ='🐑 양고기 커리'!E50 -> 14000 | F30: ='🐑 양고기 커리'!F50 -> 1366.5248 | G30: ='🐑 양고기 커리'!G50 -> 9244.1589 | H30: ='🐑 양고기 커리'!H50 -> 7877.6342 | I30: ='🐑 양고기 커리'!I50 -> 0.56268816 | J30: =IFERROR('🐑 양고기 커리'!E50-'🐑 양고기 커리'!H50,"") -> 6122.3658 | K30: ='🐑 양고기 커리'!J50 -> 🔴 과다
B31: 15 | C31: 머턴 코르마 | D31: 🐑 양고기 커리 | E31: ='🐑 양고기 커리'!E71 -> 14000 | F31: ='🐑 양고기 커리'!F71 -> 1381.0248 | G31: ='🐑 양고기 커리'!G71 -> 9244.1589 | H31: ='🐑 양고기 커리'!H71 -> 7863.1342 | I31: ='🐑 양고기 커리'!I71 -> 0.56165244 | J31: =IFERROR('🐑 양고기 커리'!E71-'🐑 양고기 커리'!H71,"") -> 6136.8658 | K31: ='🐑 양고기 커리'!J71 -> 🔴 과다
B32: 16 | C32: 머턴 빈달루 | D32: 🐑 양고기 커리 | E32: ='🐑 양고기 커리'!E92 -> 15000 | F32: ='🐑 양고기 커리'!F92 -> 2297.4136 | G32: ='🐑 양고기 커리'!G92 -> 9904.456 | H32: ='🐑 양고기 커리'!H92 -> 7607.0424 | I32: ='🐑 양고기 커리'!I92 -> 0.50713616 | J32: =IFERROR('🐑 양고기 커리'!E92-'🐑 양고기 커리'!H92,"") -> 7392.9576 | K32: ='🐑 양고기 커리'!J92 -> 🔴 과다
B33: 17 | C33: 머턴 아차르 | D33: 🐑 양고기 커리 | E33: ='🐑 양고기 커리'!E113 -> 14000 | F33: ='🐑 양고기 커리'!F113 -> 1170.8754 | G33: ='🐑 양고기 커리'!G113 -> 9244.1589 | H33: ='🐑 양고기 커리'!H113 -> 8073.2836 | I33: ='🐑 양고기 커리'!I113 -> 0.57666311 | J33: =IFERROR('🐑 양고기 커리'!E113-'🐑 양고기 커리'!H113,"") -> 5926.7164 | K33: ='🐑 양고기 커리'!J113 -> 🔴 과다
B34: 75 | C34: 머턴 사그 | D34: 🐑 양고기 커리 | E34: ='🐑 양고기 커리'!E134 -> 15000 | F34: ='🐑 양고기 커리'!F134 -> 1538.0213 | G34: ='🐑 양고기 커리'!G134 -> 9904.456 | H34: ='🐑 양고기 커리'!H134 -> 8366.4347 | I34: ='🐑 양고기 커리'!I134 -> 0.55776231 | J34: =IFERROR('🐑 양고기 커리'!E134-'🐑 양고기 커리'!H134,"") -> 6633.5653 | K34: ='🐑 양고기 커리'!J134 -> 🔴 과다
B35: 🥚 에그·해산물 커리
B36: 11 | C36: 에그 커리 | D36: 🥚 에그·해산물 커리 | E36: ='🥚 에그·해산물 커리'!E8 -> 11000 | F36: ='🥚 에그·해산물 커리'!F8 -> 1258.0248 | G36: ='🥚 에그·해산물 커리'!G8 -> 7263.2677 | H36: ='🥚 에그·해산물 커리'!H8 -> 6005.243 | I36: ='🥚 에그·해산물 커리'!I8 -> 0.54593118 | J36: =IFERROR('🥚 에그·해산물 커리'!E8-'🥚 에그·해산물 커리'!H8,"") -> 4994.757 | K36: ='🥚 에그·해산물 커리'!J8 -> 🔴 과다
B37: 18 | C37: 프라운커리 | D37: 🥚 에그·해산물 커리 | E37: ='🥚 에그·해산물 커리'!E29 -> 13000 | F37: ='🥚 에그·해산물 커리'!F29 -> 1358.496 | G37: ='🥚 에그·해산물 커리'!G29 -> 8583.8619 | H37: ='🥚 에그·해산물 커리'!H29 -> 7225.3658 | I37: ='🥚 에그·해산물 커리'!I29 -> 0.55579737 | J37: =IFERROR('🥚 에그·해산물 커리'!E29-'🥚 에그·해산물 커리'!H29,"") -> 5774.6342 | K37: ='🥚 에그·해산물 커리'!J29 -> 🔴 과다
B38: 19 | C38: 프라운 칠리 커리 | D38: 🥚 에그·해산물 커리 | E38: ='🥚 에그·해산물 커리'!E50 -> 13000 | F38: ='🥚 에그·해산물 커리'!F50 -> 2029.3581 | G38: ='🥚 에그·해산물 커리'!G50 -> 8583.8619 | H38: ='🥚 에그·해산물 커리'!H50 -> 6554.5038 | I38: ='🥚 에그·해산물 커리'!I50 -> 0.5041926 | J38: =IFERROR('🥚 에그·해산물 커리'!E50-'🥚 에그·해산물 커리'!H50,"") -> 6445.4962 | K38: ='🥚 에그·해산물 커리'!J50 -> 🔴 과다
B39: 20 | C39: 해산물 빈달루 | D39: 🥚 에그·해산물 커리 | E39: ='🥚 에그·해산물 커리'!E71 -> 15000 | F39: ='🥚 에그·해산물 커리'!F71 -> 1877.6914 | G39: ='🥚 에그·해산물 커리'!G71 -> 9904.456 | H39: ='🥚 에그·해산물 커리'!H71 -> 8026.7646 | I39: ='🥚 에그·해산물 커리'!I71 -> 0.53511764 | J39: =IFERROR('🥚 에그·해산물 커리'!E71-'🥚 에그·해산물 커리'!H71,"") -> 6973.2354 | K39: ='🥚 에그·해산물 커리'!J71 -> 🔴 과다
B40: 🥦 야채·달 커리
B41: 21 | C41: 머라이 코프타 | D41: 🥦 야채·달 커리 | E41: ='🥦 야채·달 커리'!E8 -> 13000 | F41: ='🥦 야채·달 커리'!F8 -> 1411.8471 | G41: ='🥦 야채·달 커리'!G8 -> 8583.8619 | H41: ='🥦 야채·달 커리'!H8 -> 7172.0147 | I41: ='🥦 야채·달 커리'!I8 -> 0.55169344 | J41: =IFERROR('🥦 야채·달 커리'!E8-'🥦 야채·달 커리'!H8,"") -> 5827.9853 | K41: ='🥦 야채·달 커리'!J8 -> 🔴 과다
B42: 22 | C42: 퍼니르 버터 마살라 | D42: 🥦 야채·달 커리 | E42: ='🥦 야채·달 커리'!E29 -> 13000 | F42: ='🥦 야채·달 커리'!F29 -> 1612.2748 | G42: ='🥦 야채·달 커리'!G29 -> 8583.8619 | H42: ='🥦 야채·달 커리'!H29 -> 6971.5871 | I42: ='🥦 야채·달 커리'!I29 -> 0.53627593 | J42: =IFERROR('🥦 야채·달 커리'!E29-'🥦 야채·달 커리'!H29,"") -> 6028.4129 | K42: ='🥦 야채·달 커리'!J29 -> 🔴 과다
B43: 23 | C43: 펄럭 퍼니르 | D43: 🥦 야채·달 커리 | E43: ='🥦 야채·달 커리'!E50 -> 13000 | F43: ='🥦 야채·달 커리'!F50 -> 1875.6298 | G43: ='🥦 야채·달 커리'!G50 -> 8583.8619 | H43: ='🥦 야채·달 커리'!H50 -> 6708.2321 | I43: ='🥦 야채·달 커리'!I50 -> 0.51601785 | J43: =IFERROR('🥦 야채·달 커리'!E50-'🥦 야채·달 커리'!H50,"") -> 6291.7679 | K43: ='🥦 야채·달 커리'!J50 -> 🔴 과다
B44: 24 | C44: 알루 펄럭 | D44: 🥦 야채·달 커리 | E44: ='🥦 야채·달 커리'!E71 -> 12000 | F44: ='🥦 야채·달 커리'!F71 -> 1678.1298 | G44: ='🥦 야채·달 커리'!G71 -> 7923.5648 | H44: ='🥦 야채·달 커리'!H71 -> 6245.435 | I44: ='🥦 야채·달 커리'!I71 -> 0.52045292 | J44: =IFERROR('🥦 야채·달 커리'!E71-'🥦 야채·달 커리'!H71,"") -> 5754.565 | K44: ='🥦 야채·달 커리'!J71 -> 🔴 과다
B45: 25 | C45: 알루 고비 | D45: 🥦 야채·달 커리 | E45: ='🥦 야채·달 커리'!E92 -> 12000 | F45: ='🥦 야채·달 커리'!F92 -> 436.76238 | G45: ='🥦 야채·달 커리'!G92 -> 7923.5648 | H45: ='🥦 야채·달 커리'!H92 -> 7486.8024 | I45: ='🥦 야채·달 커리'!I92 -> 0.6239002 | J45: =IFERROR('🥦 야채·달 커리'!E92-'🥦 야채·달 커리'!H92,"") -> 4513.1976 | K45: ='🥦 야채·달 커리'!J92 -> 🔴 과다
B46: 26 | C46: 쩌나 마살라 | D46: 🥦 야채·달 커리 | E46: ='🥦 야채·달 커리'!E113 -> 12000 | F46: ='🥦 야채·달 커리'!F113 -> 563.86006 | G46: ='🥦 야채·달 커리'!G113 -> 7923.5648 | H46: ='🥦 야채·달 커리'!H113 -> 7359.7047 | I46: ='🥦 야채·달 커리'!I113 -> 0.61330873 | J46: =IFERROR('🥦 야채·달 커리'!E113-'🥦 야채·달 커리'!H113,"") -> 4640.2953 | K46: ='🥦 야채·달 커리'!J113 -> 🔴 과다
...

Sheet 🥬 식재료 DB
B2: EVEREST RESTAURANT GROUP · 식재료 단가 데이터베이스
B4: 📌 노란색 셀(구매가격)을 수정하면 g당 단가가 자동 재계산되어 전체 카테고리 시트 및 대시보드에 즉시 반영됩니다.
B6: No. | C6: 식재료명 | D6: 구매가격 (원) | E6: 단위수량 | F6: 단위 | G6: 중량 (g) | H6: g당 단가 (원)
B7: 1 | C7: 중2등급 밀가루 | D7: 15000 | E7: 20 | F7: kg | G7: 20000 | H7: =IF(G7>0,D7/G7,0) -> 0.75
B8: 2 | C8: 고급 밀가루 | D8: 25000 | E8: 20 | F8: kg | G8: 20000 | H8: =IF(G8>0,D8/G8,0) -> 1.25
B9: 3 | C9: 국내산쌀 | D9: 62000 | E9: 20 | F9: kg | G9: 20000 | H9: =IF(G9>0,D9/G9,0) -> 3.1
B10: 4 | C10: 양파 | D10: 14000 | E10: 15 | F10: kg | G10: 15000 | H10: =IF(G10>0,D10/G10,0) -> 0.93333333
B11: 5 | C11: 감자 | D11: 35000 | E11: 20 | F11: kg | G11: 20000 | H11: =IF(G11>0,D11/G11,0) -> 1.75
B12: 6 | C12: 주름감자(프렌치프라이) | D12: 8300 | E12: 2 | F12: kg | G12: 2000 | H12: =IF(G12>0,D12/G12,0) -> 4.15
B13: 7 | C13: 통생강 | D13: 10000 | E13: 1 | F13: kg | G13: 1000 | H13: =IF(G13>0,D13/G13,0) -> 10
B14: 8 | C14: 통마늘 | D14: 9000 | E14: 1 | F14: kg | G14: 1000 | H14: =IF(G14>0,D14/G14,0) -> 9
B15: 9 | C15: 고운 고추가루 | D15: 14000 | E15: 1 | F15: kg | G15: 1000 | H15: =IF(G15>0,D15/G15,0) -> 14
B16: 10 | C16: 베트남(고추가루) | D16: 18000 | E16: 1 | F16: kg | G16: 1000 | H16: =IF(G16>0,D16/G16,0) -> 18
B17: 11 | C17: 베트남(건고추) | D17: 17000 | E17: 1 | F17: kg | G17: 1000 | H17: =IF(G17>0,D17/G17,0) -> 17
B18: 12 | C18: 통계피 | D18: 5000 | E18: 0.5 | F18: kg | G18: 500 | H18: =IF(G18>0,D18/G18,0) -> 10
... B125: 119 | C125: 마요네즈 소스 | D125: 14000 | E125: 3.2 | F125: kg | G125: 3200 | H125: =IF(G125>0,D125/G125,0) -> 4.375

Sheet 💰 고정비용 DB
B2: EVEREST RESTAURANT GROUP · 고정비용 데이터베이스
B4: 📌 노란색 셀(금액)을 수정하면 모든 카테고리 시트의 고정비용 배분이 자동 재계산됩니다.
B5: 📌 배분 방식: 메뉴별 고정비용 = 해당 메뉴 판매가 × 월 총고정비용 ÷ 월 추정 매출 (판매가 비례 배분)
B7: 📋 2025년 월간 고정비용 내역
B8: No. | C8: 비용 항목 | D8: 월간 금액 (원) | E8: 내용 / 비고
B9: 1 | C9: 급여 | D9: 12000000 | E9: 임금
B10: 2 | C10: 세금·지방세 | D10: 205800 | E10: 세금신고 + 지방세
B11: 3 | C11: 4대 보험료 | D11: 2336970 | E11: 사업장 4대 보험 (사용자 부담분)
B12: 4 | C12: 유틸리티 | D12: 783420 | E12: 수도·전기·가스
B13: 5 | C13: 부가가치세 | D13: 8800000 | E13: 배달의민족·쿠팡이츠 등
B14: 6 | C14: 포장 용품비 | D14: 50000 | E14: 포장재료비
B15: 7 | C15: 임대 및 광고비 | D15: 3894139 | E15: 임대료, 인터넷 마케팅, 대리운전 광고 등
B16: 8 | C16: 외상 매입금-식재료비 | D16: 17000000 | E16: 식재료비
B17: 9 | C17: 주류대금 | D17: 204000 | E17: 주류구입
B18: 10 | C18: 세무·장부 수수료 | D18: 391270 | E18: 세무신고 + 증빙 수수료
B19: 11 | C19: 기타 관리비 | D19: 703730 | E19: 잡비 기타
B20: 12 | C20: 통신비 | D20: 48950 | E20: KT 등 통신
B21: 13 | C21: 식재료 공급 계약비 | D21: 256800 | E21: 식재료 공급업체 계약 비용
B22: 합 계 | D22: =SUM(D9:D21) -> 46675079
B24: ⚙️ 배분 기준 설정 (전체 카테고리 시트 연동)
C25: 월 추정 매출 (원) | D25: 70688000 | E25: 배달 포함 월 총매출 추정 — 🟡 노란 셀 수정 가능
C26: 총 고정비용 비율 | D26: =D22/D25 -> 0.66029707
C27: 메뉴당 배분 산식 | D27: 판매가 × D22 ÷ D25 (카테고리 시트에서 자동 산출) | E27: 각 메뉴 시트에서 판매가 × 총고정비 ÷ 월매출로 자동 산출됨

Sheet 🍗 닭고기 커리
B2: EVEREST RESTAURANT GROUP · 🍗 닭고기 커리 원가 계산표
B4: 📌 녹색=자동계산 노란색=입력값 | 식재료 DB/고정비용 DB 수정 시 자동 갱신됩니다.
B5: 📌 ▣ 색상 헤더 행: E=판매가 F=식재료원가 G=고정비용배분 H=총원가 I=총원가율 J=판정
B7: No. | C7: 식재료명 | D7: 구분 | E7: 사용량(g) | F7: 수율(%) | G7: g당 단가(원) | H7: 재료 원가(원) | I7: 비고
C8: 🍽 치킨머커니 | E8: 13000 | F8: =IFERROR(SUM(H10,H11,H12,H13,H14,H15,H16,H17,H18,H19,H20,H21,H23,H24,H25,H26,H27),0) -> 1734.247 | G8: =IFERROR(E8*'💰 고정비용 DB'!$D$22/'💰 고정비용 DB'!$D$25,0) -> 8583.8619 | H8: =IFERROR(G8-F8,"") -> 6849.6149 | I8: =IFERROR(H8/E8,"") -> 0.52689345 | J8: =IF(I8="","⬜ 미입력",IF(I8<=0.2,"✅ 양호",IF(I8<=0.32,"🟡 주의","🔴 과다"))) -> 🔴 과다
B9: ▸ 메인 식재료
B10: 1 | C10: 가슴 대한 | D10: 메인 | E10: 100 | F10: 1 | G10: =IFERROR(VLOOKUP(C10,'🥬 식재료 DB'!$C$7:$H$121,6,0),"") -> 4.4 | H10: =IFERROR(IF(AND(C10<>"",ISNUMBER(E10),ISNUMBER(F10),F10>0,ISNUMBER(G10)),E10/F10*G10,""),"") -> 440
B11: 2 | C11: 체리알 | D11: 메인 | E11: 5 | F11: 1 | G11: =IFERROR(VLOOKUP(C11,'🥬 식재료 DB'!$C$7:$H$121,6,0),"") -> 12 | H11: =IFERROR(IF(AND(C11<>"",ISNUMBER(E11),ISNUMBER(F11),F11>0,ISNUMBER(G11)),E11/F11*G11,""),"") -> 60
B12: 3 | C12: 고수 | D12: 메인 | E12: 5 | F12: 1 | G12: =IFERROR(VLOOKUP(C12,'🥬 식재료 DB'!$C$7:$H$121,6,0),"") -> 18 | H12: =IFERROR(IF(AND(C12<>"",ISNUMBER(E12),ISNUMBER(F12),F12>0,ISNUMBER(G12)),E12/F12*G12,""),"") -> 90
B13: 4 | C13: 설탕 | D13: 메인 | E13: 30 | F13: 1 | G13: =IFERROR(VLOOKUP(C13,'🥬 식재료 DB'!$C$7:$H$121,6,0),"") -> 1.3333333 | H13: =IFERROR(IF(AND(C13<>"",ISNUMBER(E13),ISNUMBER(F13),F13>0,ISNUMBER(G13)),E13/F13*G13,""),"") -> 40
B14: 5 | C14: 통생강 | D14: 메인 | E14: 2 | F14: 0.9 | G14: =IFERROR(VLOOKUP(C14,'🥬 식재료 DB'!$C$7:$H$121,6,0),"") -> 10 | H14: =IFERROR(IF(AND(C14<>"",ISNUMBER(E14),ISNUMBER(F14),F14>0,ISNUMBER(G14)),E14/F14*G14,""),"") -> 22.222222
B15: 6 | C15: 토마토홀 | D15: 메인 | E15: 15 | F15: 1 | G15: =IFERROR(VLOOKUP(C15,'🥬 식재료 DB'!$C$7:$H$121,6,0),"") -> 2.4 | H15: =IFERROR(IF(AND(C15<>"",ISNUMBER(E15),ISNUMBER(F15),F15>0,ISNUMBER(G15)),E15/F15*G15,""),"") -> 36
B16: 7 | C16: 꽃소금 | D16: 메인 | E16: 5 | F16: 1 | G16: =IFERROR(VLOOKUP(C16,'🥬 식재료 DB'!$C$7:$H$121,6,0),"") -> 1 | H16: =IFERROR(IF(AND(C16<>"",ISNUMBER(E16),ISNUMBER(F16),F16>0,ISNUMBER(G16)),E16/F16*G16,""),"") -> 5
B17: 8 | C17: 데어리쿠킹크림 | D17: 메인 | E17: 30 | F17: 1 | G17: =IFERROR(VLOOKUP(C17,'🥬 식재료 DB'!$C$7:$H$121,6,0),"") -> 4.25 | H17: =IFERROR(IF(AND(C17<>"",ISNUMBER(E17),ISNUMBER(F17),F17>0,ISNUMBER(G17)),E17/F17*G17,""),"") -> 127.5
B18: 9 | D18: 메인 | G18: =IFERROR(VLOOKUP(C18,'🥬 식재료 DB'!$C$7:$H$121,6,0),"") | H18: =IFERROR(IF(AND(C18<>"",ISNUMBER(E18),ISNUMBER(F18),F18>0,ISNUMBER(G18)),E18/F18*G18,""),"")
B19: 10 | D19: 메인 | G19: =IFERROR(VLOOKUP(C19,'🥬 식재료 DB'!$C$7:$H$121,6,0),"") | H19: =IFERROR(IF(AND(C19<>"",ISNUMBER(E19),ISNUMBER(F19),F19>0,ISNUMBER(G19)),E19/F19*G19,""),"")
B20: 11 | D20: 메인 | G20: =IFERROR(VLOOKUP(C20,'🥬 식재료 DB'!$C$7:$H$121,6,0),"") | H20: =IFERROR(IF(AND(C20<>"",ISNUMBER(E20),ISNUMBER(F20),F20>0,ISNUMBER(G20)),E20/F20*G20,""),"")
B21: 12 | D21: 메인 | G21: =IFERROR(VLOOKUP(C21,'🥬 식재료 DB'!$C$7:$H$121,6,0),"") | H21: =IFERROR(IF(AND(C21<>"",ISNUMBER(E21),ISNUMBER(F21),F21>0,ISNUMBER(G21)),E21/F21*G21,""),"")
B22: ▸ 프렙 재료 (반제품)
B23: 13 | C23: 커리 그레이비 소스 | D23: 프렙 | E23: 200 | F23: 1 | G23: =IFERROR(VLOOKUP(C23,'🧪 프렙 원가표'!$C$8:$D$18,2,0),IFERROR(VLOOKUP(C23,'🥬 식재료 DB'!$C$7:$H$121,6,0),"")) -> 2.9176238 | H23: =IFERROR(IF(AND(C23<>"",ISNUMBER(E23),ISNUMBER(F23),F23>0,ISNUMBER(G23)),E23/F23*G23,""),"") -> 583.52475
B24: 14 | C24: 치즈 | D24: 프렙 | E24: 30 | F24: 1 | G24: =IFERROR(VLOOKUP(C24,'🧪 프렙 원가표'!$C$8:$D$18,2,0),IFERROR(VLOOKUP(C24,'🥬 식재료 DB'!$C$7:$H$121,6,0),"")) -> 11 | H24: =IFERROR(IF(AND(C24<>"",ISNUMBER(E24),ISNUMBER(F24),F24>0,ISNUMBER(G24)),E24/F24*G24,""),"") -> 330
B25: 15 | D25: 프렙 | G25: =IFERROR(VLOOKUP(C25,'🧪 프렙 원가표'!$C$8:$D$18,2,0),IFERROR(VLOOKUP(C25,'🥬 식재료 DB'!$C$7:$H$121,6,0),"")) | H25: =IFERROR(IF(AND(C25<>"",ISNUMBER(E25),ISNUMBER(F25),F25>0,ISNUMBER(G25)),E25/F25*G25,""),"")
B26: 16 | D26: 프렙 | G26: =IFERROR(VLOOKUP(C26,'🧪 프렙 원가표'!$C$8:$D$18,2,0),IFERROR(VLOOKUP(C26,'🥬 식재료 DB'!$C$7:$H$121,6,0),"")) | H26: =IFERROR(IF(AND(C26<>"",ISNUMBER(E26),ISNUMBER(F26),F26>0,ISNUMBER(G26)),E26/F26*G26,""),"")
B27: 17 | D27: 프렙 | G27: =IFERROR(VLOOKUP(C27,'🧪 프렙 원가표'!$C$8:$D$18,2,0),IFERROR(VLOOKUP(C27,'🥬 식재료 DB'!$C$7:$H$121,6,0),"")) | H27: =IFERROR(IF(AND(C27<>"",ISNUMBER(E27),ISNUMBER(F27),F27>0,ISNUMBER(G27)),E27/F27*G27,""),"")
C29: 🍽 치킨 커리 | E29: 12000 | F29: =IFERROR(SUM(H31,H32,H33,H34,H35,H36,H37,H38,H39,H40,H41,H42,H44,H45,H46,H47,H48),0) -> 1558.0248 | G29: =IFERROR(E29*'💰 고정비용 DB'!$D$22/'💰 고정비용 DB'!$D$25,0) -> 7923.5648 | H29: =IFERROR(G29-F29,"") -> 6365.54 | I29: =IFERROR(H29/E29,"") -> 0.53046167 | J29: =IF(I29="","⬜ 미입력",IF(I29<=0.2,"✅ 양호",IF(I29<=0.32,"🟡 주의","🔴 과다"))) -> 🔴 과다
B30: ▸ 메인 식재료
B31: 1 | C31: 가슴 대한 | D31: 메인 | E31: 100 | F31: 1 | G31: =IFERROR(VLOOKUP(C31,'🥬 식재료 DB'!$C$7:$H$121,6,0),"") -> 4.4 | H31: =IFERROR(IF(AND(C31<>"",ISNUMBER(E31),ISNUMBER(F31),F31>0,ISNUMBER(G31)),E31/F31*G31,""),"") -> 440
B32: 2 | C32: 고수 | D32: 메인 | E32: 2 | F32: 1 | G32: =IFERROR(VLOOKUP(C32,'🥬 식재료 DB'!$C$7:$H$121,6,0),"") -> 18 | H32: =IFERROR(IF(AND(C32<>"",ISNUMBER(E32),ISNUMBER(F32),F32>0,ISNUMBER(G32)),E32/F32*G32,""),"") -> 36
B33: 3 | C33: 토마토홀 | D33: 메인 | E33: 15 | F33: 1 | G33: =IFERROR(VLOOKUP(C33,'🥬 식재료 DB'!$C$7:$H$121,6,0),"") -> 2.4 | H33: =IFERROR(IF(AND(C33<>"",ISNUMBER(E33),ISNUMBER(F33),F33>0,ISNUMBER(G33)),E33/F33*G33,""),"") -> 36
B34: 4 | C34: 꽃소금 | D34: 메인 | E34: 5 | F34: 1 | G34: =IFERROR(VLOOKUP(C34,'🥬 식재료 DB'!$C$7:$H$121,6,0),"") -> 1 | H34: =IFERROR(IF(AND(C34<>"",ISNUMBER(E34),ISNUMBER(F34),F34>0,ISNUMBER(G34)),E34/F34*G34,""),"") -> 5
B35: 5 | C35: 데어리쿠킹크림 | D35: 메인 | E35: 30 | F35: 1 | G35: =IFERROR(VLOOKUP(C35,'🥬 식재료 DB'!$C$7:$H$121,6,0),"") -> 4.25 | H35: =IFERROR(IF(AND(C35<>"",ISNUMBER(E35),ISNUMBER(F35),F35>0,ISNUMBER(G35)),E35/F35*G35,""),"") -> 127.5
B36: 6 | D36: 메인 | G36: =IFERROR(VLOOKUP(C36,'🥬 식재료 DB'!$C$7:$H$121,6,0),"") | H36: =IFERROR(IF(AND(C36<>"",ISNUMBER(E36),ISNUMBER(F36),F36>0,ISNUMBER(G36)),E36/F36*G36,""),"")
B37: 7 | D37: 메인 | G37: =IFERROR(VLOOKUP(C37,'🥬 식재료 DB'!$C$7:$H$121,6,0),"") | H37: =IFERROR(IF(AND(C37<>"",ISNUMBER(E37),ISNUMBER(F37),F37>0,ISNUMBER(G37)),E37/F37*G37,""),"")
B38: 8 | D38: 메인 | G38: =IFERROR(VLOOKUP(C38,'🥬 식재료 DB'!$C$7:$H$121,6,0),"") | H38: =IFERROR(IF(AND(C38<>"",ISNUMBER(E38),ISNUMBER(F38),F38>0,ISNUMBER(G38)),E38/F38*G38,""),"")
B39: 9 | D39: 메인 | G39: =IFERROR(VLOOKUP(C39,'🥬 식재료 DB'!$C$7:$H$121,6,0),"") | H39: =IFERROR(IF(AND(C39<>"",ISNUMBER(E39),ISNUMBER(F39),F39>0,ISNUMBER(G39)),E39/F39*G39,""),"")
B40: 10 | D40: 메인 | G40: =IFERROR(VLOOKUP(C40,'🥬 식재료 DB'!$C$7:$H$121,6,0),"") | H40: =IFERROR(IF(AND(C40<>"",ISNUMBER(E40),ISNUMBER(F40),F40>0,ISNUMBER(G40)),E40/F40*G40,""),"")
B41: 11 | D41: 메인 | G41: =IFERROR(VLOOKUP(C41,'🥬 식재료 DB'!$C$7:$H$121,6,0),"") | H41: =IFERROR(IF(AND(C41<>"",ISNUMBER(E41),ISNUMBER(F41),F41>0,ISNUMBER(G41)),E41/F41*G41,""),"")
B42: 12 | D42: 메인 | G42: =IFERROR(VLOOKUP(C42,'🥬 식재료 DB'!$C$7:$H$121,6,0),"") | H42: =IFERROR(IF(AND(C42<>"",ISNUMBER(E42),ISNUMBER(F42),F42>0,ISNUMBER(G42)),E42/F42*G42,""),"")
B43: ▸ 프렙 재료 (반제품)
B44: 13 | C44: 커리 그레이비 소스 | D44: 프렙 | E44: 200 | F44: 1 | G44: =IFERROR(VLOOKUP(C44,'🧪 프렙 원가표'!$C$8:$D$18,2,0),IFERROR(VLOOKUP(C44,'🥬 식재료 DB'!$C$7:$H$121,6,0),"")) -> 2.9176238 | H44: =IFERROR(IF(AND(C44<>"",ISNUMBER(E44),ISNUMBER(F44),F44>0,ISNUMBER(G44)),E44/F44*G44,""),"") -> 583.52475
...

Sheet 🐑 양고기 커리
B2: EVEREST RESTAURANT GROUP · 🐑 양고기 커리 원가 계산표
B4: 📌 녹색=자동계산 노란색=입력값 | 식재료 DB/고정비용 DB 수정 시 자동 갱신됩니다.
B5: 📌 ▣ 색상 헤더 행: E=판매가 F=식재료원가 G=고정비용배분 H=총원가 I=총원가율 J=판정
B7: No. | C7: 식재료명 | D7: 구분 | E7: 사용량(g) | F7: 수율(%) | G7: g당 단가(원) | H7: 재료 원가(원) | I7: 비고
C8: 🍽 머턴 커리 | E8: 13000 | F8: =IFERROR(SUM(H10,H11,H12,H13,H14,H15,H16,H17,H18,H19,H20,H21,H23,H24,H25,H26,H27),0) -> 1868.0248 | G8: =IFERROR(E8*'💰 고정비용 DB'!$D$22/'💰 고정비용 DB'!$D$25,0) -> 8583.8619 | H8: =IFERROR(G8-F8,"") -> 6715.8371 | I8: =IFERROR(H8/E8,"") -> 0.51660285 | J8: =IF(I8="","⬜ 미입력",IF(I8<=0.2,"✅ 양호",IF(I8<=0.32,"🟡 주의","🔴 과다"))) -> 🔴 과다
B9: ▸ 메인 식재료
B10: 1 | C10: 양사태살 | D10: 메인 | E10: 50 | F10: 1 | G10: =IFERROR(VLOOKUP(C10,'🥬 식재료 DB'!$C$7:$H$121,6,0),"") -> 15 | H10: =IFERROR(IF(AND(C10<>"",ISNUMBER(E10),ISNUMBER(F10),F10>0,ISNUMBER(G10)),E10/F10*G10,""),"") -> 750
B11: 2 | C11: 고수 | D11: 메인 | E11: 2 | F11: 1 | G11: =IFERROR(VLOOKUP(C11,'🥬 식재료 DB'!$C$7:$H$121,6,0),"") -> 18 | H11: =IFERROR(IF(AND(C11<>"",ISNUMBER(E11),ISNUMBER(F11),F11>0,ISNUMBER(G11)),E11/F11*G11,""),"") -> 36
B12: 3 | C12: 토마토홀 | D12: 메인 | E12: 15 | F12: 1 | G12: =IFERROR(VLOOKUP(C12,'🥬 식재료 DB'!$C$7:$H$121,6,0),"") -> 2.4 | H12: =IFERROR(IF(AND(C12<>"",ISNUMBER(E12),ISNUMBER(F12),F12>0,ISNUMBER(G12)),E12/F12*G12,""),"") -> 36
B13: 4 | C13: 꽃소금 | D13: 메인 | E13: 5 | F13: 1 | G13: =IFERROR(VLOOKUP(C13,'🥬 식재료 DB'!$C$7:$H$121,6,0),"") -> 1 | H13: =IFERROR(IF(AND(C13<>"",ISNUMBER(E13),ISNUMBER(F13),F13>0,ISNUMBER(G13)),E13/F13*G13,""),"") -> 5
B14: 5 | C14: 데어리쿠킹크림 | D14: 메인 | E14: 30 | F14: 1 | G14: =IFERROR(VLOOKUP(C14,'🥬 식재료 DB'!$C$7:$H$121,6,0),"") -> 4.25 | H14: =IFERROR(IF(AND(C14<>"",ISNUMBER(E14),ISNUMBER(F14),F14>0,ISNUMBER(G14)),E14/F14*G14,""),"") -> 127.5
B15: 6 | D15: 메인 | G15: =IFERROR(VLOOKUP(C15,'🥬 식재료 DB'!$C$7:$H$121,6,0),"") | H15: =IFERROR(IF(AND(C15<>"",ISNUMBER(E15),ISNUMBER(F15),F15>0,ISNUMBER(G15)),E15/F15*G15,""),"")
B16: 7 | D16: 메인 | G16: =IFERROR(VLOOKUP(C16,'🥬 식재료 DB'!$C$7:$H$121,6,0),"") | H16: =IFERROR(IF(AND(C16<>"",ISNUMBER(E16),ISNUMBER(F16),F16>0,ISNUMBER(G16)),E16/F16*G16,""),"")
B17: 8 | D17: 메인 | G17: =IFERROR(VLOOKUP(C17,'🥬 식재료 DB'!$C$7:$H$121,6,0),"") | H17: =IFERROR(IF(AND(C17<>"",ISNUMBER(E17),ISNUMBER(F17),F17>0,ISNUMBER(G17)),E17/F17*G17,""),"")
B18: 9 | D18: 메인 | G18: =IFERROR(VLOOKUP(C18,'🥬 식재료 DB'!$C$7:$H$121,6,0),"") | H18: =IFERROR(IF(AND(C18<>"",ISNUMBER(E18),ISNUMBER(F18),F18>0,ISNUMBER(G18)),E18/F18*G18,""),"")
B19: 10 | D19: 메인 | G19: =IFERROR(VLOOKUP(C19,'🥬 식재료 DB'!$C$7:$H$121,6,0),"") | H19: =IFERROR(IF(AND(C19<>"",ISNUMBER(E19),ISNUMBER(F19),F19>0,ISNUMBER(G19)),E19/F19*G19,""),"")
B20: 11 | D20: 메인 | G20: =IFERROR(VLOOKUP(C20,'🥬 식재료 DB'!$C$7:$H$121,6,0),"") | H20: =IFERROR(IF(AND(C20<>"",ISNUMBER(E20),ISNUMBER(F20),F20>0,ISNUMBER(G20)),E20/F20*G20,""),"")
B21: 12 | D21: 메인 | G21: =IFERROR(VLOOKUP(C21,'🥬 식재료 DB'!$C$7:$H$121,6,0),"") | H21: =IFERROR(IF(AND(C21<>"",ISNUMBER(E21),ISNUMBER(F21),F21>0,ISNUMBER(G21)),E21/F21*G21,""),"")
B22: ▸ 프렙 재료 (반제품)
B23: 13 | C23: 커리 그레이비 소스 | D23: 프렙 | E23: 200 | F23: 1 | G23: =IFERROR(VLOOKUP(C23,'🧪 프렙 원가표'!$C$8:$D$18,2,0),IFERROR(VLOOKUP(C23,'🥬 식재료 DB'!$C$7:$H$121,6,0),"")) -> 2.9176238 | H23: =IFERROR(IF(AND(C23<>"",ISNUMBER(E23),ISNUMBER(F23),F23>0,ISNUMBER(G23)),E23/F23*G23,""),"") -> 583.52475
B24: 14 | C24: 치즈 | D24: 프렙 | E24: 30 | F24: 1 | G24: =IFERROR(VLOOKUP(C24,'🧪 프렙 원가표'!$C$8:$D$18,2,0),IFERROR(VLOOKUP(C24,'🥬 식재료 DB'!$C$7:$H$121,6,0),"")) -> 11 | H24: =IFERROR(IF(AND(C24<>"",ISNUMBER(E24),ISNUMBER(F24),F24>0,ISNUMBER(G24)),E24/F24*G24,""),"") -> 330
B25: 15 | D25: 프렙 | G25: =IFERROR(VLOOKUP(C25,'🧪 프렙 원가표'!$C$8:$D$18,2,0),IFERROR(VLOOKUP(C25,'🥬 식재료 DB'!$C$7:$H$121,6,0),"")) | H25: =IFERROR(IF(AND(C25<>"",ISNUMBER(E25),ISNUMBER(F25),F25>0,ISNUMBER(G25)),E25/F25*G25,""),"")
B26: 16 | D26: 프렙 | G26: =IFERROR(VLOOKUP(C26,'🧪 프렙 원가표'!$C$8:$D$18,2,0),IFERROR(VLOOKUP(C26,'🥬 식재료 DB'!$C$7:$H$121,6,0),"")) | H26: =IFERROR(IF(AND(C26<>"",ISNUMBER(E26),ISNUMBER(F26),F26>0,ISNUMBER(G26)),E26/F26*G26,""),"")
B27: 17 | D27: 프렙 | G27: =IFERROR(VLOOKUP(C27,'🧪 프렙 원가표'!$C$8:$D$18,2,0),IFERROR(VLOOKUP(C27,'🥬 식재료 DB'!$C$7:$H$121,6,0),"")) | H27: =IFERROR(IF(AND(C27<>"",ISNUMBER(E27),ISNUMBER(F27),F27>0,ISNUMBER(G27)),E27/F27*G27,""),"")
C29: 🍽 머턴 마살라 | E29: 14000 | F29: =IFERROR(SUM(H31,H32,H33,H34,H35,H36,H37,H38,H39,H40,H41,H42,H44,H45,H46,H47,H48),0) -> 2135.3998 | G29: =IFERROR(E29*'💰 고정비용 DB'!$D$22/'💰 고정비용 DB'!$D$25,0) -> 9244.1589 | H29: =IFERROR(G29-F29,"") -> 7108.7592 | I29: =IFERROR(H29/E29,"") -> 0.50776851 | J29: =IF(I29="","⬜ 미입력",IF(I29<=0.2,"✅ 양호",IF(I29<=0.32,"🟡 주의","🔴 과다"))) -> 🔴 과다
B30: ▸ 메인 식재료
B31: 1 | C31: 양사태살 | D31: 메인 | E31: 50 | F31: 1 | G31: =IFERROR(VLOOKUP(C31,'🥬 식재료 DB'!$C$7:$H$121,6,0),"") -> 15 | H31: =IFERROR(IF(AND(C31<>"",ISNUMBER(E31),ISNUMBER(F31),F31>0,ISNUMBER(G31)),E31/F31*G31,""),"") -> 750
B32: 2 | C32: 청양고추 | D32: 메인 | E32: 15 | F32: 1 | G32: =IFERROR(VLOOKUP(C32,'🥬 식재료 DB'!$C$7:$H$121,6,0),"") -> 14 | H32: =IFERROR(IF(AND(C32<>"",ISNUMBER(E32),ISNUMBER(F32),F32>0,ISNUMBER(G32)),E32/F32*G32,""),"") -> 210
B33: 3 | C33: 꽃소금 | D33: 메인 | E33: 5 | F33: 1 | G33: =IFERROR(VLOOKUP(C33,'🥬 식재료 DB'!$C$7:$H$121,6,0),"") -> 1 | H33: =IFERROR(IF(AND(C33<>"",ISNUMBER(E33),ISNUMBER(F33),F33>0,ISNUMBER(G33)),E33/F33*G33,""),"") -> 5
B34: 4 | C34: 토마토 | D34: 메인 | E34: 15 | F34: 1 | G34: =IFERROR(VLOOKUP(C34,'🥬 식재료 DB'!$C$7:$H$121,6,0),"") -> 6 | H34: =IFERROR(IF(AND(C34<>"",ISNUMBER(E34),ISNUMBER(F34),F34>0,ISNUMBER(G34)),E34/F34*G34,""),"") -> 90
B35: 5 | C35: 데어리쿠킹크림 | D35: 메인 | E35: 30 | F35: 1 | G35: =IFERROR(VLOOKUP(C35,'🥬 식재료 DB'!$C$7:$H$121,6,0),"") -> 4.25 | H35: =IFERROR(IF(AND(C35<>"",ISNUMBER(E35),ISNUMBER(F35),F35>0,ISNUMBER(G35)),E35/F35*G35,""),"") -> 127.5
B36: 6 | C36: 완두콩 | D36: 메인 | E36: 15 | F36: 1 | G36: =IFERROR(VLOOKUP(C36,'🥬 식재료 DB'!$C$7:$H$121,6,0),"") -> 2.625 | H36: =IFERROR(IF(AND(C36<>"",ISNUMBER(E36),ISNUMBER(F36),F36>0,ISNUMBER(G36)),E36/F36*G36,""),"") -> 39.375
B37: 7 | D37: 메인 | G37: =IFERROR(VLOOKUP(C37,'🥬 식재료 DB'!$C$7:$H$121,6,0),"") | H37: =IFERROR(IF(AND(C37<>"",ISNUMBER(E37),ISNUMBER(F37),F37>0,ISNUMBER(G37)),E37/F37*G37,""),"")
B38: 8 | D38: 메인 | G38: =IFERROR(VLOOKUP(C38,'🥬 식재료 DB'!$C$7:$H$121,6,0),"") | H38: =IFERROR(IF(AND(C38<>"",ISNUMBER(E38),ISNUMBER(F38),F38>0,ISNUMBER(G38)),E38/F38*G38,""),"")
B39: 9 | D39: 메인 | G39: =IFERROR(VLOOKUP(C39,'🥬 식재료 DB'!$C$7:$H$121,6,0),"") | H39: =IFERROR(IF(AND(C39<>"",ISNUMBER(E39),ISNUMBER(F39),F39>0,ISNUMBER(G39)),E39/F39*G39,""),"")
B40: 10 | D40: 메인 | G40: =IFERROR(VLOOKUP(C40,'🥬 식재료 DB'!$C$7:$H$121,6,0),"") | H40: =IFERROR(IF(AND(C40<>"",ISNUMBER(E40),ISNUMBER(F40),F40>0,ISNUMBER(G40)),E40/F40*G40,""),"")
B41: 11 | D41: 메인 | G41: =IFERROR(VLOOKUP(C41,'🥬 식재료 DB'!$C$7:$H$121,6,0),"") | H41: =IFERROR(IF(AND(C41<>"",ISNUMBER(E41),ISNUMBER(F41),F41>0,ISNUMBER(G41)),E41/F41*G41,""),"")
B42: 12 | D42: 메인 | G42: =IFERROR(VLOOKUP(C42,'🥬 식재료 DB'!$C$7:$H$121,6,0),"") | H42: =IFERROR(IF(AND(C42<>"",ISNUMBER(E42),ISNUMBER(F42),F42>0,ISNUMBER(G42)),E42/F42*G42,""),"")
B43: ▸ 프렙 재료 (반제품)
B44: 13 | C44: 커리 그레이비 소스 | D44: 프렙 | E44: 200 | F44: 1 | G44: =IFERROR(VLOOKUP(C44,'🧪 프렙 원가표'!$C$8:$D$18,2,0),IFERROR(VLOOKUP(C44,'🥬 식재료 DB'!$C$7:$H$121,6,0),"")) -> 2.9176238 | H44: =IFERROR(IF(AND(C44<>"",ISNUMBER(E44),ISNUMBER(F44),F44>0,ISNUMBER(G44)),E44/F44*G44,""),"") -> 583.52475
...

Sheet 🥚 에그·해산물 커리
B2: EVEREST RESTAURANT GROUP · 🥚 에그·해산물 커리 원가 계산표
B4: 📌 녹색=자동계산 노란색=입력값 | 식재료 DB/고정비용 DB 수정 시 자동 갱신됩니다.
B5: 📌 ▣ 색상 헤더 행: E=판매가 F=식재료원가 G=고정비용배분 H=총원가 I=총원가율 J=판정
B7: No. | C7: 식재료명 | D7: 구분 | E7: 사용량(g) | F7: 수율(%) | G7: g당 단가(원) | H7: 재료 원가(원) | I7: 비고
C8: 🍽 에그 커리 | E8: 11000 | F8: =IFERROR(SUM(H10,H11,H12,H13,H14,H15,H16,H17,H18,H19,H20,H21,H23,H24,H25,H26,H27),0) -> 1258.0248 | G8: =IFERROR(E8*'💰 고정비용 DB'!$D$22/'💰 고정비용 DB'!$D$25,0) -> 7263.2677 | H8: =IFERROR(G8-F8,"") -> 6005.243 | I8: =IFERROR(H8/E8,"") -> 0.54593118 | J8: =IF(I8="","⬜ 미입력",IF(I8<=0.2,"✅ 양호",IF(I8<=0.32,"🟡 주의","🔴 과다"))) -> 🔴 과다
B9: ▸ 메인 식재료
B10: 1 | C10: 계란 | D10: 메인 | E10: 130 | F10: 1 | G10: =IFERROR(VLOOKUP(C10,'🥬 식재료 DB'!$C$7:$H$121,6,0),"") -> 3.2307692 | H10: =IFERROR(IF(AND(C10<>"",ISNUMBER(E10),ISNUMBER(F10),F10>0,ISNUMBER(G10)),E10/F10*G10,""),"") -> 420
B11: 2 | C11: 고수 | D11: 메인 | E11: 2 | F11: 1 | G11: =IFERROR(VLOOKUP(C11,'🥬 식재료 DB'!$C$7:$H$121,6,0),"") -> 18 | H11: =IFERROR(IF(AND(C11<>"",ISNUMBER(E11),ISNUMBER(F11),F11>0,ISNUMBER(G11)),E11/F11*G11,""),"") -> 36
B12: 3 | C12: 토마토홀 | D12: 메인 | E12: 15 | F12: 1 | G12: =IFERROR(VLOOKUP(C12,'🥬 식재료 DB'!$C$7:$H$121,6,0),"") -> 2.4 | H12: =IFERROR(IF(AND(C12<>"",ISNUMBER(E12),ISNUMBER(F12),F12>0,ISNUMBER(G12)),E12/F12*G12,""),"") -> 36
B13: 4 | C13: 꽃소금 | D13: 메인 | E13: 5 | F13: 1 | G13: =IFERROR(VLOOKUP(C13,'🥬 식재료 DB'!$C$7:$H$121,6,0),"") -> 1 | H13: =IFERROR(IF(AND(C13<>"",ISNUMBER(E13),ISNUMBER(F13),F13>0,ISNUMBER(G13)),E13/F13*G13,""),"") -> 5
B14: 5 | C14: 데어리쿠킹크림 | D14: 메인 | E14: 30 | F14: 1 | G14: =IFERROR(VLOOKUP(C14,'🥬 식재료 DB'!$C$7:$H$121,6,0),"") -> 4.25 | H14: =IFERROR(IF(AND(C14<>"",ISNUMBER(E14),ISNUMBER(F14),F14>0,ISNUMBER(G14)),E14/F14*G14,""),"") -> 127.5
B15: 6 | C15: 통생강 | D15: 메인 | E15: 5 | F15: 1 | G15: =IFERROR(VLOOKUP(C15,'🥬 식재료 DB'!$C$7:$H$121,6,0),"") -> 10 | H15: =IFERROR(IF(AND(C15<>"",ISNUMBER(E15),ISNUMBER(F15),F15>0,ISNUMBER(G15)),E15/F15*G15,""),"") -> 50
B16: 7 | D16: 메인 | G16: =IFERROR(VLOOKUP(C16,'🥬 식재료 DB'!$C$7:$H$121,6,0),"") | H16: =IFERROR(IF(AND(C16<>"",ISNUMBER(E16),ISNUMBER(F16),F16>0,ISNUMBER(G16)),E16/F16*G16,""),"")
B17: 8 | D17: 메인 | G17: =IFERROR(VLOOKUP(C17,'🥬 식재료 DB'!$C$7:$H$121,6,0),"") | H17: =IFERROR(IF(AND(C17<>"",ISNUMBER(E17),ISNUMBER(F17),F17>0,ISNUMBER(G17)),E17/F17*G17,""),"")
B18: 9 | D18: 메인 | G18: =IFERROR(VLOOKUP(C18,'🥬 식재료 DB'!$C$7:$H$121,6,0),"") | H18: =IFERROR(IF(AND(C18<>"",ISNUMBER(E18),ISNUMBER(F18),F18>0,ISNUMBER(G18)),E18/F18*G18,""),"")
B19: 10 | D19: 메인 | G19: =IFERROR(VLOOKUP(C19,'🥬 식재료 DB'!$C$7:$H$121,6,0),"") | H19: =IFERROR(IF(AND(C19<>"",ISNUMBER(E19),ISNUMBER(F19),F19>0,ISNUMBER(G19)),E19/F19*G19,""),"")
B20: 11 | D20: 메인 | G20: =IFERROR(VLOOKUP(C20,'🥬 식재료 DB'!$C$7:$H$121,6,0),"") | H20: =IFERROR(IF(AND(C20<>"",ISNUMBER(E20),ISNUMBER(F20),F20>0,ISNUMBER(G20)),E20/F20*G20,""),"")
B21: 12 | D21: 메인 | G21: =IFERROR(VLOOKUP(C21,'🥬 식재료 DB'!$C$7:$H$121,6,0),"") | H21: =IFERROR(IF(AND(C21<>"",ISNUMBER(E21),ISNUMBER(F21),F21>0,ISNUMBER(G21)),E21/F21*G21,""),"")
B22: ▸ 프렙 재료 (반제품)
B23: 13 | C23: 커리 그레이비 소스 | D23: 프렙 | E23: 200 | F23: 1 | G23: =IFERROR(VLOOKUP(C23,'🧪 프렙 원가표'!$C$8:$D$18,2,0),IFERROR(VLOOKUP(C23,'🥬 식재료 DB'!$C$7:$H$121,6,0),"")) -> 2.9176238 | H23: =IFERROR(IF(AND(C23<>"",ISNUMBER(E23),ISNUMBER(F23),F23>0,ISNUMBER(G23)),E23/F23*G23,""),"") -> 583.52475
B24: 14 | D24: 프렙 | G24: =IFERROR(VLOOKUP(C24,'🧪 프렙 원가표'!$C$8:$D$18,2,0),IFERROR(VLOOKUP(C24,'🥬 식재료 DB'!$C$7:$H$121,6,0),"")) | H24: =IFERROR(IF(AND(C24<>"",ISNUMBER(E24),ISNUMBER(F24),F24>0,ISNUMBER(G24)),E24/F24*G24,""),"")
B25: 15 | D25: 프렙 | G25: =IFERROR(VLOOKUP(C25,'🧪 프렙 원가표'!$C$8:$D$18,2,0),IFERROR(VLOOKUP(C25,'🥬 식재료 DB'!$C$7:$H$121,6,0),"")) | H25: =IFERROR(IF(AND(C25<>"",ISNUMBER(E25),ISNUMBER(F25),F25>0,ISNUMBER(G25)),E25/F25*G25,""),"")
B26: 16 | D26: 프렙 | G26: =IFERROR(VLOOKUP(C26,'🧪 프렙 원가표'!$C$8:$D$18,2,0),IFERROR(VLOOKUP(C26,'🥬 식재료 DB'!$C$7:$H$121,6,0),"")) | H26: =IFERROR(IF(AND(C26<>"",ISNUMBER(E26),ISNUMBER(F26),F26>0,ISNUMBER(G26)),E26/F26*G26,""),"")
B27: 17 | D27: 프렙 | G27: =IFERROR(VLOOKUP(C27,'🧪 프렙 원가표'!$C$8:$D$18,2,0),IFERROR(VLOOKUP(C27,'🥬 식재료 DB'!$C$7:$H$121,6,0),"")) | H27: =IFERROR(IF(AND(C27<>"",ISNUMBER(E27),ISNUMBER(F27),F27>0,ISNUMBER(G27)),E27/F27*G27,""),"")
C29: 🍽 프라운커리 | E29: 13000 | F29: =IFERROR(SUM(H31,H32,H33,H34,H35,H36,H37,H38,H39,H40,H41,H42,H44,H45,H46,H47,H48),0) -> 1358.496 | G29: =IFERROR(E29*'💰 고정비용 DB'!$D$22/'💰 고정비용 DB'!$D$25,0) -> 8583.8619 | H29: =IFERROR(G29-F29,"") -> 7225.3658 | I29: =IFERROR(H29/E29,"") -> 0.55579737 | J29: =IF(I29="","⬜ 미입력",IF(I29<=0.2,"✅ 양호",IF(I29<=0.32,"🟡 주의","🔴 과다"))) -> 🔴 과다
B30: ▸ 메인 식재료
B31: 1 | C31: 찐새우살 | D31: 메인 | E31: 45 | F31: 1 | G31: =IFERROR(VLOOKUP(C31,'🥬 식재료 DB'!$C$7:$H$121,6,0),"") -> 16.666667 | H31: =IFERROR(IF(AND(C31<>"",ISNUMBER(E31),ISNUMBER(F31),F31>0,ISNUMBER(G31)),E31/F31*G31,""),"") -> 750
B32: 2 | C32: 토마토 | D32: 메인 | E32: 10 | F32: 1 | G32: =IFERROR(VLOOKUP(C32,'🥬 식재료 DB'!$C$7:$H$121,6,0),"") -> 6 | H32: =IFERROR(IF(AND(C32<>"",ISNUMBER(E32),ISNUMBER(F32),F32>0,ISNUMBER(G32)),E32/F32*G32,""),"") -> 60
B33: 3 | C33: 데어리쿠킹크림 | D33: 메인 | E33: 10 | F33: 1 | G33: =IFERROR(VLOOKUP(C33,'🥬 식재료 DB'!$C$7:$H$121,6,0),"") -> 4.25 | H33: =IFERROR(IF(AND(C33<>"",ISNUMBER(E33),ISNUMBER(F33),F33>0,ISNUMBER(G33)),E33/F33*G33,""),"") -> 42.5
B34: 4 | C34: 꽃소금 | D34: 메인 | E34: 10 | F34: 1 | G34: =IFERROR(VLOOKUP(C34,'🥬 식재료 DB'!$C$7:$H$121,6,0),"") -> 1 | H34: =IFERROR(IF(AND(C34<>"",ISNUMBER(E34),ISNUMBER(F34),F34>0,ISNUMBER(G34)),E34/F34*G34,""),"") -> 10
B35: 5 | C35: 기 | D35: 메인 | E35: 10 | F35: 1 | G35: =IFERROR(VLOOKUP(C35,'🥬 식재료 DB'!$C$7:$H$121,6,0),"") | H35: =IFERROR(IF(AND(C35<>"",ISNUMBER(E35),ISNUMBER(F35),F35>0,ISNUMBER(G35)),E35/F35*G35,""),"")
B36: 6 | D36: 메인 | G36: =IFERROR(VLOOKUP(C36,'🥬 식재료 DB'!$C$7:$H$121,6,0),"") | H36: =IFERROR(IF(AND(C36<>"",ISNUMBER(E36),ISNUMBER(F36),F36>0,ISNUMBER(G36)),E36/F36*G36,""),"")
B37: 7 | D37: 메인 | G37: =IFERROR(VLOOKUP(C37,'🥬 식재료 DB'!$C$7:$H$121,6,0),"") | H37: =IFERROR(IF(AND(C37<>"",ISNUMBER(E37),ISNUMBER(F37),F37>0,ISNUMBER(G37)),E37/F37*G37,""),"")
B38: 8 | D38: 메인 | G38: =IFERROR(VLOOKUP(C38,'🥬 식재료 DB'!$C$7:$H$121,6,0),"") | H38: =IFERROR(IF(AND(C38<>"",ISNUMBER(E38),ISNUMBER(F38),F38>0,ISNUMBER(G38)),E38/F38*G38,""),"")
B39: 9 | D39: 메인 | G39: =IFERROR(VLOOKUP(C39,'🥬 식재료 DB'!$C$7:$H$121,6,0),"") | H39: =IFERROR(IF(AND(C39<>"",ISNUMBER(E39),ISNUMBER(F39),F39>0,ISNUMBER(G39)),E39/F39*G39,""),"")
B40: 10 | D40: 메인 | G40: =IFERROR(VLOOKUP(C40,'🥬 식재료 DB'!$C$7:$H$121,6,0),"") | H40: =IFERROR(IF(AND(C40<>"",ISNUMBER(E40),ISNUMBER(F40),F40>0,ISNUMBER(G40)),E40/F40*G40,""),"")
B41: 11 | D41: 메인 | G41: =IFERROR(VLOOKUP(C41,'🥬 식재료 DB'!$C$7:$H$121,6,0),"") | H41: =IFERROR(IF(AND(C41<>"",ISNUMBER(E41),ISNUMBER(F41),F41>0,ISNUMBER(G41)),E41/F41*G41,""),"")
B42: 12 | D42: 메인 | G42: =IFERROR(VLOOKUP(C42,'🥬 식재료 DB'!$C$7:$H$121,6,0),"") | H42: =IFERROR(IF(AND(C42<>"",ISNUMBER(E42),ISNUMBER(F42),F42>0,ISNUMBER(G42)),E42/F42*G42,""),"")
B43: ▸ 프렙 재료 (반제품)
B44: 13 | C44: 커리 그레이비 소스 | D44: 프렙 | E44: 170 | F44: 1 | G44: =IFERROR(VLOOKUP(C44,'🧪 프렙 원가표'!$C$8:$D$18,2,0),IFERROR(VLOOKUP(C44,'🥬 식재료 DB'!$C$7:$H$121,6,0),"")) -> 2.9176238 | H44: =IFERROR(IF(AND(C44<>"",ISNUMBER(E44),ISNUMBER(F44),F44>0,ISNUMBER(G44)),E44/F44*G44,""),"") -> 495.99604
...

Sheet 🥦 야채·달 커리
B2: EVEREST RESTAURANT GROUP · 🥦 야채·달 커리 원가 계산표
B4: 📌 녹색=자동계산 노란색=입력값 | 식재료 DB/고정비용 DB 수정 시 자동 갱신됩니다.
B5: 📌 ▣ 색상 헤더 행: E=판매가 F=식재료원가 G=고정비용배분 H=총원가 I=총원가율 J=판정
B7: No. | C7: 식재료명 | D7: 구분 | E7: 사용량(g) | F7: 수율(%) | G7: g당 단가(원) | H7: 재료 원가(원) | I7: 비고
C8: 🍽 머라이 코프타 | E8: 13000 | F8: =IFERROR(SUM(H10,H11,H12,H13,H14,H15,H16,H17,H18,H19,H20,H21,H23,H24,H25,H26,H27),0) -> 1411.8471 | G8: =IFERROR(E8*'💰 고정비용 DB'!$D$22/'💰 고정비용 DB'!$D$25,0) -> 8583.8619 | H8: =IFERROR(G8-F8,"") -> 7172.0147 | I8: =IFERROR(H8/E8,"") -> 0.55169344 | J8: =IF(I8="","⬜ 미입력",IF(I8<=0.2,"✅ 양호",IF(I8<=0.32,"🟡 주의","🔴 과다"))) -> 🔴 과다
B9: ▸ 메인 식재료
B10: 1 | C10: 감자 | D10: 메인 | E10: 50 | F10: 1 | G10: =IFERROR(VLOOKUP(C10,'🥬 식재료 DB'!$C$7:$H$121,6,0),"") -> 1.75 | H10: =IFERROR(IF(AND(C10<>"",ISNUMBER(E10),ISNUMBER(F10),F10>0,ISNUMBER(G10)),E10/F10*G10,""),"") -> 87.5
B11: 2 | C11: 캐슈넛 | D11: 메인 | E11: 10 | F11: 1 | G11: =IFERROR(VLOOKUP(C11,'🥬 식재료 DB'!$C$7:$H$121,6,0),"") -> 12.894737 | H11: =IFERROR(IF(AND(C11<>"",ISNUMBER(E11),ISNUMBER(F11),F11>0,ISNUMBER(G11)),E11/F11*G11,""),"") -> 128.94737
B12: 3 | C12: 중2등급 밀가루 | D12: 메인 | E12: 5 | F12: 1 | G12: =IFERROR(VLOOKUP(C12,'🥬 식재료 DB'!$C$7:$H$121,6,0),"") -> 0.75 | H12: =IFERROR(IF(AND(C12<>"",ISNUMBER(E12),ISNUMBER(F12),F12>0,ISNUMBER(G12)),E12/F12*G12,""),"") -> 3.75
B13: 4 | C13: 토마토 | D13: 메인 | E13: 10 | F13: 1 | G13: =IFERROR(VLOOKUP(C13,'🥬 식재료 DB'!$C$7:$H$121,6,0),"") -> 6 | H13: =IFERROR(IF(AND(C13<>"",ISNUMBER(E13),ISNUMBER(F13),F13>0,ISNUMBER(G13)),E13/F13*G13,""),"") -> 60
B14: 5 | C14: 설탕 | D14: 메인 | E14: 30 | F14: 1 | G14: =IFERROR(VLOOKUP(C14,'🥬 식재료 DB'!$C$7:$H$121,6,0),"") -> 1.3333333 | H14: =IFERROR(IF(AND(C14<>"",ISNUMBER(E14),ISNUMBER(F14),F14>0,ISNUMBER(G14)),E14/F14*G14,""),"") -> 40
B15: 6 | C15: 데어리쿠킹크림 | D15: 메인 | E15: 30 | F15: 1 | G15: =IFERROR(VLOOKUP(C15,'🥬 식재료 DB'!$C$7:$H$121,6,0),"") -> 4.25 | H15: =IFERROR(IF(AND(C15<>"",ISNUMBER(E15),ISNUMBER(F15),F15>0,ISNUMBER(G15)),E15/F15*G15,""),"") -> 127.5
B16: 7 | C16: 꽃소금 | D16: 메인 | E16: 15 | F16: 1 | G16: =IFERROR(VLOOKUP(C16,'🥬 식재료 DB'!$C$7:$H$121,6,0),"") -> 1 | H16: =IFERROR(IF(AND(C16<>"",ISNUMBER(E16),ISNUMBER(F16),F16>0,ISNUMBER(G16)),E16/F16*G16,""),"") -> 15
B17: 8 | C17: ASEEL PURE GHEE | D17: 메인 | E17: 5 | F17: 1 | G17: =IFERROR(VLOOKUP(C17,'🥬 식재료 DB'!$C$7:$H$121,6,0),"") -> 18.125 | H17: =IFERROR(IF(AND(C17<>"",ISNUMBER(E17),ISNUMBER(F17),F17>0,ISNUMBER(G17)),E17/F17*G17,""),"") -> 90.625
B18: 9 | D18: 메인 | G18: =IFERROR(VLOOKUP(C18,'🥬 식재료 DB'!$C$7:$H$121,6,0),"") | H18: =IFERROR(IF(AND(C18<>"",ISNUMBER(E18),ISNUMBER(F18),F18>0,ISNUMBER(G18)),E18/F18*G18,""),"")
B19: 10 | D19: 메인 | G19: =IFERROR(VLOOKUP(C19,'🥬 식재료 DB'!$C$7:$H$121,6,0),"") | H19: =IFERROR(IF(AND(C19<>"",ISNUMBER(E19),ISNUMBER(F19),F19>0,ISNUMBER(G19)),E19/F19*G19,""),"")
B20: 11 | D20: 메인 | G20: =IFERROR(VLOOKUP(C20,'🥬 식재료 DB'!$C$7:$H$121,6,0),"") | H20: =IFERROR(IF(AND(C20<>"",ISNUMBER(E20),ISNUMBER(F20),F20>0,ISNUMBER(G20)),E20/F20*G20,""),"")
B21: 12 | D21: 메인 | G21: =IFERROR(VLOOKUP(C21,'🥬 식재료 DB'!$C$7:$H$121,6,0),"") | H21: =IFERROR(IF(AND(C21<>"",ISNUMBER(E21),ISNUMBER(F21),F21>0,ISNUMBER(G21)),E21/F21*G21,""),"")
B22: ▸ 프렙 재료 (반제품)
B23: 13 | C23: 커리 그레이비 소스 | D23: 프렙 | E23: 200 | F23: 1 | G23: =IFERROR(VLOOKUP(C23,'🧪 프렙 원가표'!$C$8:$D$18,2,0),IFERROR(VLOOKUP(C23,'🥬 식재료 DB'!$C$7:$H$121,6,0),"")) -> 2.9176238 | H23: =IFERROR(IF(AND(C23<>"",ISNUMBER(E23),ISNUMBER(F23),F23>0,ISNUMBER(G23)),E23/F23*G23,""),"") -> 583.52475
B24: 14 | C24: 치즈 | D24: 프렙 | E24: 25 | F24: 1 | G24: =IFERROR(VLOOKUP(C24,'🧪 프렙 원가표'!$C$8:$D$18,2,0),IFERROR(VLOOKUP(C24,'🥬 식재료 DB'!$C$7:$H$121,6,0),"")) -> 11 | H24: =IFERROR(IF(AND(C24<>"",ISNUMBER(E24),ISNUMBER(F24),F24>0,ISNUMBER(G24)),E24/F24*G24,""),"") -> 275
B25: 15 | D25: 프렙 | G25: =IFERROR(VLOOKUP(C25,'🧪 프렙 원가표'!$C$8:$D$18,2,0),IFERROR(VLOOKUP(C25,'🥬 식재료 DB'!$C$7:$H$121,6,0),"")) | H25: =IFERROR(IF(AND(C25<>"",ISNUMBER(E25),ISNUMBER(F25),F25>0,ISNUMBER(G25)),E25/F25*G25,""),"")
B26: 16 | D26: 프렙 | G26: =IFERROR(VLOOKUP(C26,'🧪 프렙 원가표'!$C$8:$D$18,2,0),IFERROR(VLOOKUP(C26,'🥬 식재료 DB'!$C$7:$H$121,6,0),"")) | H26: =IFERROR(IF(AND(C26<>"",ISNUMBER(E26),ISNUMBER(F26),F26>0,ISNUMBER(G26)),E26/F26*G26,""),"")
B27: 17 | D27: 프렙 | G27: =IFERROR(VLOOKUP(C27,'🧪 프렙 원가표'!$C$8:$D$18,2,0),IFERROR(VLOOKUP(C27,'🥬 식재료 DB'!$C$7:$H$121,6,0),"")) | H27: =IFERROR(IF(AND(C27<>"",ISNUMBER(E27),ISNUMBER(F27),F27>0,ISNUMBER(G27)),E27/F27*G27,""),"")
C29: 🍽 퍼니르 버터 마살라 | E29: 13000 | F29: =IFERROR(SUM(H31,H32,H33,H34,H35,H36,H37,H38,H39,H40,H41,H42,H44,H45,H46,H47,H48),0) -> 1612.2748 | G29: =IFERROR(E29*'💰 고정비용 DB'!$D$22/'💰 고정비용 DB'!$D$25,0) -> 8583.8619 | H29: =IFERROR(G29-F29,"") -> 6971.5871 | I29: =IFERROR(H29/E29,"") -> 0.53627593 | J29: =IF(I29="","⬜ 미입력",IF(I29<=0.2,"✅ 양호",IF(I29<=0.32,"🟡 주의","🔴 과다"))) -> 🔴 과다
B30: ▸ 메인 식재료
B31: 1 | C31: 토마토 | D31: 메인 | E31: 10 | F31: 1 | G31: =IFERROR(VLOOKUP(C31,'🥬 식재료 DB'!$C$7:$H$121,6,0),"") -> 6 | H31: =IFERROR(IF(AND(C31<>"",ISNUMBER(E31),ISNUMBER(F31),F31>0,ISNUMBER(G31)),E31/F31*G31,""),"") -> 60
B32: 2 | C32: 설탕 | D32: 메인 | E32: 30 | F32: 1 | G32: =IFERROR(VLOOKUP(C32,'🥬 식재료 DB'!$C$7:$H$121,6,0),"") -> 1.3333333 | H32: =IFERROR(IF(AND(C32<>"",ISNUMBER(E32),ISNUMBER(F32),F32>0,ISNUMBER(G32)),E32/F32*G32,""),"") -> 40
B33: 3 | C33: 데어리쿠킹크림 | D33: 메인 | E33: 30 | F33: 1 | G33: =IFERROR(VLOOKUP(C33,'🥬 식재료 DB'!$C$7:$H$121,6,0),"") -> 4.25 | H33: =IFERROR(IF(AND(C33<>"",ISNUMBER(E33),ISNUMBER(F33),F33>0,ISNUMBER(G33)),E33/F33*G33,""),"") -> 127.5
B34: 4 | C34: 꽃소금 | D34: 메인 | E34: 15 | F34: 1 | G34: =IFERROR(VLOOKUP(C34,'🥬 식재료 DB'!$C$7:$H$121,6,0),"") -> 1 | H34: =IFERROR(IF(AND(C34<>"",ISNUMBER(E34),ISNUMBER(F34),F34>0,ISNUMBER(G34)),E34/F34*G34,""),"") -> 15
B35: 5 | C35: ASEEL PURE GHEE | D35: 메인 | E35: 10 | F35: 1 | G35: =IFERROR(VLOOKUP(C35,'🥬 식재료 DB'!$C$7:$H$121,6,0),"") -> 18.125 | H35: =IFERROR(IF(AND(C35<>"",ISNUMBER(E35),ISNUMBER(F35),F35>0,ISNUMBER(G35)),E35/F35*G35,""),"") -> 181.25
B36: 6 | D36: 메인 | G36: =IFERROR(VLOOKUP(C36,'🥬 식재료 DB'!$C$7:$H$121,6,0),"") | H36: =IFERROR(IF(AND(C36<>"",ISNUMBER(E36),ISNUMBER(F36),F36>0,ISNUMBER(G36)),E36/F36*G36,""),"")
B37: 7 | D37: 메인 | G37: =IFERROR(VLOOKUP(C37,'🥬 식재료 DB'!$C$7:$H$121,6,0),"") | H37: =IFERROR(IF(AND(C37<>"",ISNUMBER(E37),ISNUMBER(F37),F37>0,ISNUMBER(G37)),E37/F37*G37,""),"")
B38: 8 | D38: 메인 | G38: =IFERROR(VLOOKUP(C38,'🥬 식재료 DB'!$C$7:$H$121,6,0),"") | H38: =IFERROR(IF(AND(C38<>"",ISNUMBER(E38),ISNUMBER(F38),F38>0,ISNUMBER(G38)),E38/F38*G38,""),"")
B39: 9 | D39: 메인 | G39: =IFERROR(VLOOKUP(C39,'🥬 식재료 DB'!$C$7:$H$121,6,0),"") | H39: =IFERROR(IF(AND(C39<>"",ISNUMBER(E39),ISNUMBER(F39),F39>0,ISNUMBER(G39)),E39/F39*G39,""),"")
B40: 10 | D40: 메인 | G40: =IFERROR(VLOOKUP(C40,'🥬 식재료 DB'!$C$7:$H$121,6,0),"") | H40: =IFERROR(IF(AND(C40<>"",ISNUMBER(E40),ISNUMBER(F40),F40>0,ISNUMBER(G40)),E40/F40*G40,""),"")
B41: 11 | D41: 메인 | G41: =IFERROR(VLOOKUP(C41,'🥬 식재료 DB'!$C$7:$H$121,6,0),"") | H41: =IFERROR(IF(AND(C41<>"",ISNUMBER(E41),ISNUMBER(F41),F41>0,ISNUMBER(G41)),E41/F41*G41,""),"")
B42: 12 | D42: 메인 | G42: =IFERROR(VLOOKUP(C42,'🥬 식재료 DB'!$C$7:$H$121,6,0),"") | H42: =IFERROR(IF(AND(C42<>"",ISNUMBER(E42),ISNUMBER(F42),F42>0,ISNUMBER(G42)),E42/F42*G42,""),"")
B43: ▸ 프렙 재료 (반제품)
B44: 13 | C44: 치즈 | D44: 프렙 | E44: 55 | F44: 1 | G44: =IFERROR(VLOOKUP(C44,'🧪 프렙 원가표'!$C$8:$D$18,2,0),IFERROR(VLOOKUP(C44,'🥬 식재료 DB'!$C$7:$H$121,6,0),"")) -> 11 | H44: =IFERROR(IF(AND(C44<>"",ISNUMBER(E44),ISNUMBER(F44),F44>0,ISNUMBER(G44)),E44/F44*G44,""),"") -> 605
...

Sheet 🔥 탄두리·케밥
B2: EVEREST RESTAURANT GROUP · 🔥 탄두리·케밥 원가 계산표
B4: 📌 녹색=자동계산 노란색=입력값 | 식재료 DB/고정비용 DB 수정 시 자동 갱신됩니다.
B5: 📌 ▣ 색상 헤더 행: E=판매가 F=식재료원가 G=고정비용배분 H=총원가 I=총원가율 J=판정
B7: No. | C7: 식재료명 | D7: 구분 | E7: 사용량(g) | F7: 수율(%) | G7: g당 단가(원) | H7: 재료 원가(원) | I7: 비고
C8: 🍽 치킨 멀라이 케밥 | E8: 12000 | F8: =IFERROR(SUM(H10,H11,H12,H13,H14,H15,H16,H17,H18,H19,H20,H21,H23,H24,H25,H26,H27),0) -> 594.34211 | G8: =IFERROR(E8*'💰 고정비용 DB'!$D$22/'💰 고정비용 DB'!$D$25,0) -> 7923.5648 | H8: =IFERROR(G8-F8,"") -> 7329.2227 | I8: =IFERROR(H8/E8,"") -> 0.61076856 | J8: =IF(I8="","⬜ 미입력",IF(I8<=0.2,"✅ 양호",IF(I8<=0.32,"🟡 주의","🔴 과다"))) -> 🔴 과다
B9: ▸ 메인 식재료
B10: 1 | C10: 닭 (부위 정육) | D10: 메인 | E10: 250 | F10: 1 | G10: =IFERROR(VLOOKUP(C10,'🥬 식재료 DB'!$C$7:$H$121,6,0),"") | H10: =IFERROR(IF(AND(C10<>"",ISNUMBER(E10),ISNUMBER(F10),F10>0,ISNUMBER(G10)),E10/F10*G10,""),"")
B11: 2 | C11: 데어리쿠킹크림 | D11: 메인 | E11: 20 | F11: 1 | G11: =IFERROR(VLOOKUP(C11,'🥬 식재료 DB'!$C$7:$H$121,6,0),"") -> 4.25 | H11: =IFERROR(IF(AND(C11<>"",ISNUMBER(E11),ISNUMBER(F11),F11>0,ISNUMBER(G11)),E11/F11*G11,""),"") -> 85
B12: 3 | C12: 캐슈넛 | D12: 메인 | E12: 30 | F12: 1 | G12: =IFERROR(VLOOKUP(C12,'🥬 식재료 DB'!$C$7:$H$121,6,0),"") -> 12.894737 | H12: =IFERROR(IF(AND(C12<>"",ISNUMBER(E12),ISNUMBER(F12),F12>0,ISNUMBER(G12)),E12/F12*G12,""),"") -> 386.84211
B13: 4 | C13: 백후추가루 | D13: 메인 | E13: 5 | F13: 1 | G13: =IFERROR(VLOOKUP(C13,'🥬 식재료 DB'!$C$7:$H$121,6,0),"") -> 22.5 | H13: =IFERROR(IF(AND(C13<>"",ISNUMBER(E13),ISNUMBER(F13),F13>0,ISNUMBER(G13)),E13/F13*G13,""),"") -> 112.5
B14: 5 | C14: 꽃소금 | D14: 메인 | E14: 10 | F14: 1 | G14: =IFERROR(VLOOKUP(C14,'🥬 식재료 DB'!$C$7:$H$121,6,0),"") -> 1 | H14: =IFERROR(IF(AND(C14<>"",ISNUMBER(E14),ISNUMBER(F14),F14>0,ISNUMBER(G14)),E14/F14*G14,""),"") -> 10
B15: 6 | D15: 메인 | G15: =IFERROR(VLOOKUP(C15,'🥬 식재료 DB'!$C$7:$H$121,6,0),"") | H15: =IFERROR(IF(AND(C15<>"",ISNUMBER(E15),ISNUMBER(F15),F15>0,ISNUMBER(G15)),E15/F15*G15,""),"")
B16: 7 | D16: 메인 | G16: =IFERROR(VLOOKUP(C16,'🥬 식재료 DB'!$C$7:$H$121,6,0),"") | H16: =IFERROR(IF(AND(C16<>"",ISNUMBER(E16),ISNUMBER(F16),F16>0,ISNUMBER(G16)),E16/F16*G16,""),"")
B17: 8 | D17: 메인 | G17: =IFERROR(VLOOKUP(C17,'🥬 식재료 DB'!$C$7:$H$121,6,0),"") | H17: =IFERROR(IF(AND(C17<>"",ISNUMBER(E17),ISNUMBER(F17),F17>0,ISNUMBER(G17)),E17/F17*G17,""),"")
B18: 9 | D18: 메인 | G18: =IFERROR(VLOOKUP(C18,'🥬 식재료 DB'!$C$7:$H$121,6,0),"") | H18: =IFERROR(IF(AND(C18<>"",ISNUMBER(E18),ISNUMBER(F18),F18>0,ISNUMBER(G18)),E18/F18*G18,""),"")
B19: 10 | D19: 메인 | G19: =IFERROR(VLOOKUP(C19,'🥬 식재료 DB'!$C$7:$H$121,6,0),"") | H19: =IFERROR(IF(AND(C19<>"",ISNUMBER(E19),ISNUMBER(F19),F19>0,ISNUMBER(G19)),E19/F19*G19,""),"")
B20: 11 | D20: 메인 | G20: =IFERROR(VLOOKUP(C20,'🥬 식재료 DB'!$C$7:$H$121,6,0),"") | H20: =IFERROR(IF(AND(C20<>"",ISNUMBER(E20),ISNUMBER(F20),F20>0,ISNUMBER(G20)),E20/F20*G20,""),"")
B21: 12 | D21: 메인 | G21: =IFERROR(VLOOKUP(C21,'🥬 식재료 DB'!$C$7:$H$121,6,0),"") | H21: =IFERROR(IF(AND(C21<>"",ISNUMBER(E21),ISNUMBER(F21),F21>0,ISNUMBER(G21)),E21/F21*G21,""),"")
B22: ▸ 프렙 재료 (반제품)
B23: 13 | C23: 탄두리 샐라드 | D23: 프렙 | E23: 30 | F23: 1 | G23: =IFERROR(VLOOKUP(C23,'🧪 프렙 원가표'!$C$8:$D$18,2,0),IFERROR(VLOOKUP(C23,'🥬 식재료 DB'!$C$7:$H$121,6,0),"")) | H23: =IFERROR(IF(AND(C23<>"",ISNUMBER(E23),ISNUMBER(F23),F23>0,ISNUMBER(G23)),E23/F23*G23,""),"")
B24: 14 | D24: 프렙 | G24: =IFERROR(VLOOKUP(C24,'🧪 프렙 원가표'!$C$8:$D$18,2,0),IFERROR(VLOOKUP(C24,'🥬 식재료 DB'!$C$7:$H$121,6,0),"")) | H24: =IFERROR(IF(AND(C24<>"",ISNUMBER(E24),ISNUMBER(F24),F24>0,ISNUMBER(G24)),E24/F24*G24,""),"")
B25: 15 | D25: 프렙 | G25: =IFERROR(VLOOKUP(C25,'🧪 프렙 원가표'!$C$8:$D$18,2,0),IFERROR(VLOOKUP(C25,'🥬 식재료 DB'!$C$7:$H$121,6,0),"")) | H25: =IFERROR(IF(AND(C25<>"",ISNUMBER(E25),ISNUMBER(F25),F25>0,ISNUMBER(G25)),E25/F25*G25,""),"")
B26: 16 | D26: 프렙 | G26: =IFERROR(VLOOKUP(C26,'🧪 프렙 원가표'!$C$8:$D$18,2,0),IFERROR(VLOOKUP(C26,'🥬 식재료 DB'!$C$7:$H$121,6,0),"")) | H26: =IFERROR(IF(AND(C26<>"",ISNUMBER(E26),ISNUMBER(F26),F26>0,ISNUMBER(G26)),E26/F26*G26,""),"")
B27: 17 | D27: 프렙 | G27: =IFERROR(VLOOKUP(C27,'🧪 프렙 원가표'!$C$8:$D$18,2,0),IFERROR(VLOOKUP(C27,'🥬 식재료 DB'!$C$7:$H$121,6,0),"")) | H27: =IFERROR(IF(AND(C27<>"",ISNUMBER(E27),ISNUMBER(F27),F27>0,ISNUMBER(G27)),E27/F27*G27,""),"")
C29: 🍽 치킨 티카 | E29: 11000 | F29: =IFERROR(SUM(H31,H32,H33,H34,H35,H36,H37,H38,H39,H40,H41,H42,H44,H45,H46,H47,H48),0) -> 458.16417 | G29: =IFERROR(E29*'💰 고정비용 DB'!$D$22/'💰 고정비용 DB'!$D$25,0) -> 7263.2677 | H29: =IFERROR(G29-F29,"") -> 6805.1036 | I29: =IFERROR(H29/E29,"") -> 0.61864578 | J29: =IF(I29="","⬜ 미입력",IF(I29<=0.2,"✅ 양호",IF(I29<=0.32,"🟡 주의","🔴 과다"))) -> 🔴 과다
B30: ▸ 메인 식재료
B31: 1 | C31: 닭 (부위 정육) | D31: 메인 | E31: 250 | F31: 1 | G31: =IFERROR(VLOOKUP(C31,'🥬 식재료 DB'!$C$7:$H$121,6,0),"") | H31: =IFERROR(IF(AND(C31<>"",ISNUMBER(E31),ISNUMBER(F31),F31>0,ISNUMBER(G31)),E31/F31*G31,""),"")
B32: 2 | C32: 치킨 마살라 파우더 | D32: 메인 | E32: 5 | F32: 1 | G32: =IFERROR(VLOOKUP(C32,'🥬 식재료 DB'!$C$7:$H$121,6,0),"") | H32: =IFERROR(IF(AND(C32<>"",ISNUMBER(E32),ISNUMBER(F32),F32>0,ISNUMBER(G32)),E32/F32*G32,""),"")
B33: 3 | C33: CUMIN powder | D33: 메인 | E33: 5 | F33: 1 | G33: =IFERROR(VLOOKUP(C33,'🥬 식재료 DB'!$C$7:$H$121,6,0),"") -> 22.5 | H33: =IFERROR(IF(AND(C33<>"",ISNUMBER(E33),ISNUMBER(F33),F33>0,ISNUMBER(G33)),E33/F33*G33,""),"") -> 112.5
B34: 4 | C34: 베트남 고추가루 | D34: 메인 | E34: 5 | F34: 1 | G34: =IFERROR(VLOOKUP(C34,'🥬 식재료 DB'!$C$7:$H$121,6,0),"") | H34: =IFERROR(IF(AND(C34<>"",ISNUMBER(E34),ISNUMBER(F34),F34>0,ISNUMBER(G34)),E34/F34*G34,""),"")
B35: 5 | C35: 꽃소금 | D35: 메인 | E35: 5 | F35: 1 | G35: =IFERROR(VLOOKUP(C35,'🥬 식재료 DB'!$C$7:$H$121,6,0),"") -> 1 | H35: =IFERROR(IF(AND(C35<>"",ISNUMBER(E35),ISNUMBER(F35),F35>0,ISNUMBER(G35)),E35/F35*G35,""),"") -> 5
B36: 6 | C36: 식용유 | D36: 메인 | E36: 5 | F36: 1 | G36: =IFERROR(VLOOKUP(C36,'🥬 식재료 DB'!$C$7:$H$121,6,0),"") -> 2.75 | H36: =IFERROR(IF(AND(C36<>"",ISNUMBER(E36),ISNUMBER(F36),F36>0,ISNUMBER(G36)),E36/F36*G36,""),"") -> 13.75
B37: 7 | C37: 레몬 | D37: 메인 | E37: 10 | F37: 1 | G37: =IFERROR(VLOOKUP(C37,'🥬 식재료 DB'!$C$7:$H$121,6,0),"") -> 9 | H37: =IFERROR(IF(AND(C37<>"",ISNUMBER(E37),ISNUMBER(F37),F37>0,ISNUMBER(G37)),E37/F37*G37,""),"") -> 90
B38: 8 | D38: 메인 | G38: =IFERROR(VLOOKUP(C38,'🥬 식재료 DB'!$C$7:$H$121,6,0),"") | H38: =IFERROR(IF(AND(C38<>"",ISNUMBER(E38),ISNUMBER(F38),F38>0,ISNUMBER(G38)),E38/F38*G38,""),"")
B39: 9 | D39: 메인 | G39: =IFERROR(VLOOKUP(C39,'🥬 식재료 DB'!$C$7:$H$121,6,0),"") | H39: =IFERROR(IF(AND(C39<>"",ISNUMBER(E39),ISNUMBER(F39),F39>0,ISNUMBER(G39)),E39/F39*G39,""),"")
B40: 10 | D40: 메인 | G40: =IFERROR(VLOOKUP(C40,'🥬 식재료 DB'!$C$7:$H$121,6,0),"") | H40: =IFERROR(IF(AND(C40<>"",ISNUMBER(E40),ISNUMBER(F40),F40>0,ISNUMBER(G40)),E40/F40*G40,""),"")
B41: 11 | D41: 메인 | G41: =IFERROR(VLOOKUP(C41,'🥬 식재료 DB'!$C$7:$H$121,6,0),"") | H41: =IFERROR(IF(AND(C41<>"",ISNUMBER(E41),ISNUMBER(F41),F41>0,ISNUMBER(G41)),E41/F41*G41,""),"")
B42: 12 | D42: 메인 | G42: =IFERROR(VLOOKUP(C42,'🥬 식재료 DB'!$C$7:$H$121,6,0),"") | H42: =IFERROR(IF(AND(C42<>"",ISNUMBER(E42),ISNUMBER(F42),F42>0,ISNUMBER(G42)),E42/F42*G42,""),"")
B43: ▸ 프렙 재료 (반제품)
B44: 13 | C44: 탄두리 소스 | D44: 프렙 | E44: 30 | F44: 1 | G44: =IFERROR(VLOOKUP(C44,'🧪 프렙 원가표'!$C$8:$D$18,2,0),IFERROR(VLOOKUP(C44,'🥬 식재료 DB'!$C$7:$H$121,6,0),"")) -> 7.8971389 | H44: =IFERROR(IF(AND(C44<>"",ISNUMBER(E44),ISNUMBER(F44),F44>0,ISNUMBER(G44)),E44/F44*G44,""),"") -> 236.91417
...

Sheet 🥟 스낵·면·만두
B2: EVEREST RESTAURANT GROUP · 🥟 스낵·면·만두 원가 계산표
B4: 📌 녹색=자동계산 노란색=입력값 | 식재료 DB/고정비용 DB 수정 시 자동 갱신됩니다.
B5: 📌 ▣ 색상 헤더 행: E=판매가 F=식재료원가 G=고정비용배분 H=총원가 I=총원가율 J=판정
B7: No. | C7: 식재료명 | D7: 구분 | E7: 사용량(g) | F7: 수율(%) | G7: g당 단가(원) | H7: 재료 원가(원) | I7: 비고
C8: 🍽 모모 | E8: 10000 | F8: =IFERROR(SUM(H10,H11,H12,H13,H14,H15,H16,H17,H18,H19,H20,H21,H23,H24,H25,H26,H27),0) -> 626.16667 | G8: =IFERROR(E8*'💰 고정비용 DB'!$D$22/'💰 고정비용 DB'!$D$25,0) -> 6602.9707 | H8: =IFERROR(G8-F8,"") -> 5976.804 | I8: =IFERROR(H8/E8,"") -> 0.5976804 | J8: =IF(I8="","⬜ 미입력",IF(I8<=0.2,"✅ 양호",IF(I8<=0.32,"🟡 주의","🔴 과다"))) -> 🔴 과다
B9: ▸ 메인 식재료
B10: 1 | C10: 고급 밀가루 | D10: 메인 | E10: 200 | F10: 1 | G10: =IFERROR(VLOOKUP(C10,'🥬 식재료 DB'!$C$7:$H$121,6,0),"") -> 1.25 | H10: =IFERROR(IF(AND(C10<>"",ISNUMBER(E10),ISNUMBER(F10),F10>0,ISNUMBER(G10)),E10/F10*G10,""),"") -> 250
B11: 2 | C11: 정육 (닭) | D11: 메인 | E11: 100 | F11: 1 | G11: =IFERROR(VLOOKUP(C11,'🥬 식재료 DB'!$C$7:$H$121,6,0),"") | H11: =IFERROR(IF(AND(C11<>"",ISNUMBER(E11),ISNUMBER(F11),F11>0,ISNUMBER(G11)),E11/F11*G11,""),"")
B12: 3 | C12: 양파 | D12: 메인 | E12: 20 | F12: 1 | G12: =IFERROR(VLOOKUP(C12,'🥬 식재료 DB'!$C$7:$H$121,6,0),"") -> 0.93333333 | H12: =IFERROR(IF(AND(C12<>"",ISNUMBER(E12),ISNUMBER(F12),F12>0,ISNUMBER(G12)),E12/F12*G12,""),"") -> 18.666667
B13: 4 | C13: 고수잎 | D13: 메인 | E13: 10 | F13: 1 | G13: =IFERROR(VLOOKUP(C13,'🥬 식재료 DB'!$C$7:$H$121,6,0),"") | H13: =IFERROR(IF(AND(C13<>"",ISNUMBER(E13),ISNUMBER(F13),F13>0,ISNUMBER(G13)),E13/F13*G13,""),"")
B14: 5 | C14: 통생강 | D14: 메인 | E14: 5 | F14: 1 | G14: =IFERROR(VLOOKUP(C14,'🥬 식재료 DB'!$C$7:$H$121,6,0),"") -> 10 | H14: =IFERROR(IF(AND(C14<>"",ISNUMBER(E14),ISNUMBER(F14),F14>0,ISNUMBER(G14)),E14/F14*G14,""),"") -> 50
B15: 6 | C15: 통마늘 | D15: 메인 | E15: 5 | F15: 1 | G15: =IFERROR(VLOOKUP(C15,'🥬 식재료 DB'!$C$7:$H$121,6,0),"") -> 9 | H15: =IFERROR(IF(AND(C15<>"",ISNUMBER(E15),ISNUMBER(F15),F15>0,ISNUMBER(G15)),E15/F15*G15,""),"") -> 45
B16: 7 | C16: 치킨/머턴 마살라 파우더 | D16: 메인 | E16: 10 | F16: 1 | G16: =IFERROR(VLOOKUP(C16,'🥬 식재료 DB'!$C$7:$H$121,6,0),"") | H16: =IFERROR(IF(AND(C16<>"",ISNUMBER(E16),ISNUMBER(F16),F16>0,ISNUMBER(G16)),E16/F16*G16,""),"")
B17: 8 | C17: CUMIN powder | D17: 메인 | E17: 10 | F17: 1 | G17: =IFERROR(VLOOKUP(C17,'🥬 식재료 DB'!$C$7:$H$121,6,0),"") -> 22.5 | H17: =IFERROR(IF(AND(C17<>"",ISNUMBER(E17),ISNUMBER(F17),F17>0,ISNUMBER(G17)),E17/F17*G17,""),"") -> 225
B18: 9 | C18: 꽃소금 | D18: 메인 | E18: 10 | F18: 1 | G18: =IFERROR(VLOOKUP(C18,'🥬 식재료 DB'!$C$7:$H$121,6,0),"") -> 1 | H18: =IFERROR(IF(AND(C18<>"",ISNUMBER(E18),ISNUMBER(F18),F18>0,ISNUMBER(G18)),E18/F18*G18,""),"") -> 10
B19: 10 | C19: 식용유 | D19: 메인 | E19: 10 | F19: 1 | G19: =IFERROR(VLOOKUP(C19,'🥬 식재료 DB'!$C$7:$H$121,6,0),"") -> 2.75 | H19: =IFERROR(IF(AND(C19<>"",ISNUMBER(E19),ISNUMBER(F19),F19>0,ISNUMBER(G19)),E19/F19*G19,""),"") -> 27.5
B20: 11 | D20: 메인 | G20: =IFERROR(VLOOKUP(C20,'🥬 식재료 DB'!$C$7:$H$121,6,0),"") | H20: =IFERROR(IF(AND(C20<>"",ISNUMBER(E20),ISNUMBER(F20),F20>0,ISNUMBER(G20)),E20/F20*G20,""),"")
B21: 12 | D21: 메인 | G21: =IFERROR(VLOOKUP(C21,'🥬 식재료 DB'!$C$7:$H$121,6,0),"") | H21: =IFERROR(IF(AND(C21<>"",ISNUMBER(E21),ISNUMBER(F21),F21>0,ISNUMBER(G21)),E21/F21*G21,""),"")
B22: ▸ 프렙 재료 (반제품)
B23: 13 | D23: 프렙 | G23: =IFERROR(VLOOKUP(C23,'🧪 프렙 원가표'!$C$8:$D$18,2,0),IFERROR(VLOOKUP(C23,'🥬 식재료 DB'!$C$7:$H$121,6,0),"")) | H23: =IFERROR(IF(AND(C23<>"",ISNUMBER(E23),ISNUMBER(F23),F23>0,ISNUMBER(G23)),E23/F23*G23,""),"")
B24: 14 | D24: 프렙 | G24: =IFERROR(VLOOKUP(C24,'🧪 프렙 원가표'!$C$8:$D$18,2,0),IFERROR(VLOOKUP(C24,'🥬 식재료 DB'!$C$7:$H$121,6,0),"")) | H24: =IFERROR(IF(AND(C24<>"",ISNUMBER(E24),ISNUMBER(F24),F24>0,ISNUMBER(G24)),E24/F24*G24,""),"")
B25: 15 | D25: 프렙 | G25: =IFERROR(VLOOKUP(C25,'🧪 프렙 원가표'!$C$8:$D$18,2,0),IFERROR(VLOOKUP(C25,'🥬 식재료 DB'!$C$7:$H$121,6,0),"")) | H25: =IFERROR(IF(AND(C25<>"",ISNUMBER(E25),ISNUMBER(F25),F25>0,ISNUMBER(G25)),E25/F25*G25,""),"")
B26: 16 | D26: 프렙 | G26: =IFERROR(VLOOKUP(C26,'🧪 프렙 원가표'!$C$8:$D$18,2,0),IFERROR(VLOOKUP(C26,'🥬 식재료 DB'!$C$7:$H$121,6,0),"")) | H26: =IFERROR(IF(AND(C26<>"",ISNUMBER(E26),ISNUMBER(F26),F26>0,ISNUMBER(G26)),E26/F26*G26,""),"")
B27: 17 | D27: 프렙 | G27: =IFERROR(VLOOKUP(C27,'🧪 프렙 원가표'!$C$8:$D$18,2,0),IFERROR(VLOOKUP(C27,'🥬 식재료 DB'!$C$7:$H$121,6,0),"")) | H27: =IFERROR(IF(AND(C27<>"",ISNUMBER(E27),ISNUMBER(F27),F27>0,ISNUMBER(G27)),E27/F27*G27,""),"")
C29: 🍽 졸 모모 | E29: 12000 | F29: =IFERROR(SUM(H31,H32,H33,H34,H35,H36,H37,H38,H39,H40,H41,H42,H44,H45,H46,H47,H48),0) -> 683.66667 | G29: =IFERROR(E29*'💰 고정비용 DB'!$D$22/'💰 고정비용 DB'!$D$25,0) -> 7923.5648 | H29: =IFERROR(G29-F29,"") -> 7239.8981 | I29: =IFERROR(H29/E29,"") -> 0.60332484 | J29: =IF(I29="","⬜ 미입력",IF(I29<=0.2,"✅ 양호",IF(I29<=0.32,"🟡 주의","🔴 과다"))) -> 🔴 과다
B30: ▸ 메인 식재료
B31: 1 | C31: 고급 밀가루 | D31: 메인 | E31: 200 | F31: 1 | G31: =IFERROR(VLOOKUP(C31,'🥬 식재료 DB'!$C$7:$H$121,6,0),"") -> 1.25 | H31: =IFERROR(IF(AND(C31<>"",ISNUMBER(E31),ISNUMBER(F31),F31>0,ISNUMBER(G31)),E31/F31*G31,""),"") -> 250
B32: 2 | C32: 정육 (닭) | D32: 메인 | E32: 100 | F32: 1 | G32: =IFERROR(VLOOKUP(C32,'🥬 식재료 DB'!$C$7:$H$121,6,0),"") | H32: =IFERROR(IF(AND(C32<>"",ISNUMBER(E32),ISNUMBER(F32),F32>0,ISNUMBER(G32)),E32/F32*G32,""),"")
B33: 3 | C33: 토마토 | D33: 메인 | E33: 30 | F33: 1 | G33: =IFERROR(VLOOKUP(C33,'🥬 식재료 DB'!$C$7:$H$121,6,0),"") -> 6 | H33: =IFERROR(IF(AND(C33<>"",ISNUMBER(E33),ISNUMBER(F33),F33>0,ISNUMBER(G33)),E33/F33*G33,""),"") -> 180
B34: 4 | C34: 양파 | D34: 메인 | E34: 20 | F34: 1 | G34: =IFERROR(VLOOKUP(C34,'🥬 식재료 DB'!$C$7:$H$121,6,0),"") -> 0.93333333 | H34: =IFERROR(IF(AND(C34<>"",ISNUMBER(E34),ISNUMBER(F34),F34>0,ISNUMBER(G34)),E34/F34*G34,""),"") -> 18.666667
B35: 5 | C35: CUMIN powder | D35: 메인 | E35: 10 | F35: 1 | G35: =IFERROR(VLOOKUP(C35,'🥬 식재료 DB'!$C$7:$H$121,6,0),"") -> 22.5 | H35: =IFERROR(IF(AND(C35<>"",ISNUMBER(E35),ISNUMBER(F35),F35>0,ISNUMBER(G35)),E35/F35*G35,""),"") -> 225
B36: 6 | C36: 치킨 마살라 파우더 | D36: 메인 | E36: 10 | F36: 1 | G36: =IFERROR(VLOOKUP(C36,'🥬 식재료 DB'!$C$7:$H$121,6,0),"") | H36: =IFERROR(IF(AND(C36<>"",ISNUMBER(E36),ISNUMBER(F36),F36>0,ISNUMBER(G36)),E36/F36*G36,""),"")
B37: 7 | C37: 베트남 고추가루 | D37: 메인 | E37: 10 | F37: 1 | G37: =IFERROR(VLOOKUP(C37,'🥬 식재료 DB'!$C$7:$H$121,6,0),"") | H37: =IFERROR(IF(AND(C37<>"",ISNUMBER(E37),ISNUMBER(F37),F37>0,ISNUMBER(G37)),E37/F37*G37,""),"")
B38: 8 | C38: 꽃소금 | D38: 메인 | E38: 10 | F38: 1 | G38: =IFERROR(VLOOKUP(C38,'🥬 식재료 DB'!$C$7:$H$121,6,0),"") -> 1 | H38: =IFERROR(IF(AND(C38<>"",ISNUMBER(E38),ISNUMBER(F38),F38>0,ISNUMBER(G38)),E38/F38*G38,""),"") -> 10
B39: 9 | C39: 고수잎 | D39: 메인 | E39: 10 | F39: 1 | G39: =IFERROR(VLOOKUP(C39,'🥬 식재료 DB'!$C$7:$H$121,6,0),"") | H39: =IFERROR(IF(AND(C39<>"",ISNUMBER(E39),ISNUMBER(F39),F39>0,ISNUMBER(G39)),E39/F39*G39,""),"")
B40: 10 | D40: 메인 | G40: =IFERROR(VLOOKUP(C40,'🥬 식재료 DB'!$C$7:$H$121,6,0),"") | H40: =IFERROR(IF(AND(C40<>"",ISNUMBER(E40),ISNUMBER(F40),F40>0,ISNUMBER(G40)),E40/F40*G40,""),"")
B41: 11 | D41: 메인 | G41: =IFERROR(VLOOKUP(C41,'🥬 식재료 DB'!$C$7:$H$121,6,0),"") | H41: =IFERROR(IF(AND(C41<>"",ISNUMBER(E41),ISNUMBER(F41),F41>0,ISNUMBER(G41)),E41/F41*G41,""),"")
B42: 12 | D42: 메인 | G42: =IFERROR(VLOOKUP(C42,'🥬 식재료 DB'!$C$7:$H$121,6,0),"") | H42: =IFERROR(IF(AND(C42<>"",ISNUMBER(E42),ISNUMBER(F42),F42>0,ISNUMBER(G42)),E42/F42*G42,""),"")
B43: ▸ 프렙 재료 (반제품)
B44: 13 | D44: 프렙 | G44: =IFERROR(VLOOKUP(C44,'🧪 프렙 원가표'!$C$8:$D$18,2,0),IFERROR(VLOOKUP(C44,'🥬 식재료 DB'!$C$7:$H$121,6,0),"")) | H44: =IFERROR(IF(AND(C44<>"",ISNUMBER(E44),ISNUMBER(F44),F44>0,ISNUMBER(G44)),E44/F44*G44,""),"")
...

Sheet 🫓 빵류
B2: EVEREST RESTAURANT GROUP · 🫓 빵류 원가 계산표
B4: 📌 녹색=자동계산 노란색=입력값 | 식재료 DB/고정비용 DB 수정 시 자동 갱신됩니다.
B5: 📌 ▣ 색상 헤더 행: E=판매가 F=식재료원가 G=고정비용배분 H=총원가 I=총원가율 J=판정
B7: No. | C7: 식재료명 | D7: 구분 | E7: 사용량(g) | F7: 수율(%) | G7: g당 단가(원) | H7: 재료 원가(원) | I7: 비고
C8: 🍽 허니난 | E8: 4000 | F8: =IFERROR(SUM(H10,H11,H12,H13,H14,H15,H16,H17,H18,H19,H20,H21,H23,H24,H25,H26,H27),0) -> 238 | G8: =IFERROR(E8*'💰 고정비용 DB'!$D$22/'💰 고정비용 DB'!$D$25,0) -> 2641.1883 | H8: =IFERROR(G8-F8,"") -> 2403.1883 | I8: =IFERROR(H8/E8,"") -> 0.60079707 | J8: =IF(I8="","⬜ 미입력",IF(I8<=0.2,"✅ 양호",IF(I8<=0.32,"🟡 주의","🔴 과다"))) -> 🔴 과다
B9: ▸ 메인 식재료
B10: 1 | C10: 중2등급 밀가루 | D10: 메인 | E10: 160 | F10: 1 | G10: =IFERROR(VLOOKUP(C10,'🥬 식재료 DB'!$C$7:$H$121,6,0),"") -> 0.75 | H10: =IFERROR(IF(AND(C10<>"",ISNUMBER(E10),ISNUMBER(F10),F10>0,ISNUMBER(G10)),E10/F10*G10,""),"") -> 120
B11: 2 | C11: 허니 | D11: 메인 | E11: 20 | F11: 1 | G11: =IFERROR(VLOOKUP(C11,'🥬 식재료 DB'!$C$7:$H$121,6,0),"") | H11: =IFERROR(IF(AND(C11<>"",ISNUMBER(E11),ISNUMBER(F11),F11>0,ISNUMBER(G11)),E11/F11*G11,""),"")
B12: 3 | C12: 열탄 | D12: 메인 | E12: 50 | F12: 1 | G12: =IFERROR(VLOOKUP(C12,'🥬 식재료 DB'!$C$7:$H$121,6,0),"") -> 2.36 | H12: =IFERROR(IF(AND(C12<>"",ISNUMBER(E12),ISNUMBER(F12),F12>0,ISNUMBER(G12)),E12/F12*G12,""),"") -> 118
B13: 4 | D13: 메인 | G13: =IFERROR(VLOOKUP(C13,'🥬 식재료 DB'!$C$7:$H$121,6,0),"") | H13: =IFERROR(IF(AND(C13<>"",ISNUMBER(E13),ISNUMBER(F13),F13>0,ISNUMBER(G13)),E13/F13*G13,""),"")
B14: 5 | D14: 메인 | G14: =IFERROR(VLOOKUP(C14,'🥬 식재료 DB'!$C$7:$H$121,6,0),"") | H14: =IFERROR(IF(AND(C14<>"",ISNUMBER(E14),ISNUMBER(F14),F14>0,ISNUMBER(G14)),E14/F14*G14,""),"")
B15: 6 | D15: 메인 | G15: =IFERROR(VLOOKUP(C15,'🥬 식재료 DB'!$C$7:$H$121,6,0),"") | H15: =IFERROR(IF(AND(C15<>"",ISNUMBER(E15),ISNUMBER(F15),F15>0,ISNUMBER(G15)),E15/F15*G15,""),"")
B16: 7 | D16: 메인 | G16: =IFERROR(VLOOKUP(C16,'🥬 식재료 DB'!$C$7:$H$121,6,0),"") | H16: =IFERROR(IF(AND(C16<>"",ISNUMBER(E16),ISNUMBER(F16),F16>0,ISNUMBER(G16)),E16/F16*G16,""),"")
B17: 8 | D17: 메인 | G17: =IFERROR(VLOOKUP(C17,'🥬 식재료 DB'!$C$7:$H$121,6,0),"") | H17: =IFERROR(IF(AND(C17<>"",ISNUMBER(E17),ISNUMBER(F17),F17>0,ISNUMBER(G17)),E17/F17*G17,""),"")
B18: 9 | D18: 메인 | G18: =IFERROR(VLOOKUP(C18,'🥬 식재료 DB'!$C$7:$H$121,6,0),"") | H18: =IFERROR(IF(AND(C18<>"",ISNUMBER(E18),ISNUMBER(F18),F18>0,ISNUMBER(G18)),E18/F18*G18,""),"")
